2025-03-15 21:59:02,632 -  nornir.core -     INFO -        run() - Running task 'backup_config' with args {} on 1 hosts
2025-03-15 21:59:02,638 - nornir.core.task -    ERROR -      start() - Host 'buildroom': task 'napalm_get' failed with traceback:
Traceback (most recent call last):
  File "/Users/evangoulden/.local/share/virtualenvs/nornir_netauto-sh27gIds/lib/python3.11/site-packages/nornir/core/task.py", line 98, in start
    r = self.task(self, **self.params)
        ^^^^^^^^^^^^^^^^^^^^^^^^^^^^^^
  File "/Users/evangoulden/.local/share/virtualenvs/nornir_netauto-sh27gIds/lib/python3.11/site-packages/nornir_napalm/plugins/tasks/napalm_get.py", line 32, in napalm_get
    device = task.host.get_connection(CONNECTION_NAME, task.nornir.config)
             ^^^^^^^^^^^^^^^^^^^^^^^^^^^^^^^^^^^^^^^^^^^^^^^^^^^^^^^^^^^^^
  File "/Users/evangoulden/.local/share/virtualenvs/nornir_netauto-sh27gIds/lib/python3.11/site-packages/nornir/core/inventory.py", line 476, in get_connection
    self.open_connection(
  File "/Users/evangoulden/.local/share/virtualenvs/nornir_netauto-sh27gIds/lib/python3.11/site-packages/nornir/core/inventory.py", line 528, in open_connection
    conn_obj.open(
  File "/Users/evangoulden/.local/share/virtualenvs/nornir_netauto-sh27gIds/lib/python3.11/site-packages/nornir_napalm/plugins/connections/__init__.py", line 55, in open
    network_driver = get_network_driver(platform)
                     ^^^^^^^^^^^^^^^^^^^^^^^^^^^^
  File "/Users/evangoulden/.local/share/virtualenvs/nornir_netauto-sh27gIds/lib/python3.11/site-packages/napalm/base/__init__.py", line 70, in get_network_driver
    raise ModuleImportError("Please provide a valid driver name.")
napalm.base.exceptions.ModuleImportError: Please provide a valid driver name.

2025-03-15 21:59:02,639 - nornir.core.task -    ERROR -      start() - Host 'buildroom': task 'backup_config' failed with traceback:
Traceback (most recent call last):
  File "/Users/evangoulden/.local/share/virtualenvs/nornir_netauto-sh27gIds/lib/python3.11/site-packages/nornir/core/task.py", line 98, in start
    r = self.task(self, **self.params)
        ^^^^^^^^^^^^^^^^^^^^^^^^^^^^^^
  File "/Users/evangoulden/Code/nornir_netauto/netauto.py", line 18, in backup_config
    return task.run(task=napalm_get, getters=["config"])
           ^^^^^^^^^^^^^^^^^^^^^^^^^^^^^^^^^^^^^^^^^^^^^
  File "/Users/evangoulden/.local/share/virtualenvs/nornir_netauto-sh27gIds/lib/python3.11/site-packages/nornir/core/task.py", line 173, in run
    raise NornirSubTaskError(task=run_task, result=r)
nornir.core.exceptions.NornirSubTaskError: Subtask: napalm_get (failed)


2025-03-15 21:59:35,615 -  nornir.core -     INFO -        run() - Running task 'backup_config' with args {} on 1 hosts
2025-03-15 21:59:35,616 - nornir.core.task -    ERROR -      start() - Host 'buildroom': task 'napalm_get' failed with traceback:
Traceback (most recent call last):
  File "/Users/evangoulden/.local/share/virtualenvs/nornir_netauto-sh27gIds/lib/python3.11/site-packages/nornir/core/task.py", line 98, in start
    r = self.task(self, **self.params)
        ^^^^^^^^^^^^^^^^^^^^^^^^^^^^^^
  File "/Users/evangoulden/.local/share/virtualenvs/nornir_netauto-sh27gIds/lib/python3.11/site-packages/nornir_napalm/plugins/tasks/napalm_get.py", line 32, in napalm_get
    device = task.host.get_connection(CONNECTION_NAME, task.nornir.config)
             ^^^^^^^^^^^^^^^^^^^^^^^^^^^^^^^^^^^^^^^^^^^^^^^^^^^^^^^^^^^^^
  File "/Users/evangoulden/.local/share/virtualenvs/nornir_netauto-sh27gIds/lib/python3.11/site-packages/nornir/core/inventory.py", line 476, in get_connection
    self.open_connection(
  File "/Users/evangoulden/.local/share/virtualenvs/nornir_netauto-sh27gIds/lib/python3.11/site-packages/nornir/core/inventory.py", line 528, in open_connection
    conn_obj.open(
  File "/Users/evangoulden/.local/share/virtualenvs/nornir_netauto-sh27gIds/lib/python3.11/site-packages/nornir_napalm/plugins/connections/__init__.py", line 55, in open
    network_driver = get_network_driver(platform)
                     ^^^^^^^^^^^^^^^^^^^^^^^^^^^^
  File "/Users/evangoulden/.local/share/virtualenvs/nornir_netauto-sh27gIds/lib/python3.11/site-packages/napalm/base/__init__.py", line 70, in get_network_driver
    raise ModuleImportError("Please provide a valid driver name.")
napalm.base.exceptions.ModuleImportError: Please provide a valid driver name.

2025-03-15 21:59:35,616 - nornir.core.task -    ERROR -      start() - Host 'buildroom': task 'backup_config' failed with traceback:
Traceback (most recent call last):
  File "/Users/evangoulden/.local/share/virtualenvs/nornir_netauto-sh27gIds/lib/python3.11/site-packages/nornir/core/task.py", line 98, in start
    r = self.task(self, **self.params)
        ^^^^^^^^^^^^^^^^^^^^^^^^^^^^^^
  File "/Users/evangoulden/Code/nornir_netauto/netauto.py", line 19, in backup_config
    return task.run(task=napalm_get, getters=["config"])
           ^^^^^^^^^^^^^^^^^^^^^^^^^^^^^^^^^^^^^^^^^^^^^
  File "/Users/evangoulden/.local/share/virtualenvs/nornir_netauto-sh27gIds/lib/python3.11/site-packages/nornir/core/task.py", line 173, in run
    raise NornirSubTaskError(task=run_task, result=r)
nornir.core.exceptions.NornirSubTaskError: Subtask: napalm_get (failed)


2025-03-15 22:02:29,418 -  nornir.core -     INFO -        run() - Running task 'backup_config' with args {} on 1 hosts
2025-03-15 22:02:29,419 - nornir.core.task -    ERROR -      start() - Host 'buildroom': task 'napalm_get' failed with traceback:
Traceback (most recent call last):
  File "/Users/evangoulden/.local/share/virtualenvs/nornir_netauto-sh27gIds/lib/python3.11/site-packages/nornir/core/task.py", line 98, in start
    r = self.task(self, **self.params)
        ^^^^^^^^^^^^^^^^^^^^^^^^^^^^^^
  File "/Users/evangoulden/.local/share/virtualenvs/nornir_netauto-sh27gIds/lib/python3.11/site-packages/nornir_napalm/plugins/tasks/napalm_get.py", line 32, in napalm_get
    device = task.host.get_connection(CONNECTION_NAME, task.nornir.config)
             ^^^^^^^^^^^^^^^^^^^^^^^^^^^^^^^^^^^^^^^^^^^^^^^^^^^^^^^^^^^^^
  File "/Users/evangoulden/.local/share/virtualenvs/nornir_netauto-sh27gIds/lib/python3.11/site-packages/nornir/core/inventory.py", line 476, in get_connection
    self.open_connection(
  File "/Users/evangoulden/.local/share/virtualenvs/nornir_netauto-sh27gIds/lib/python3.11/site-packages/nornir/core/inventory.py", line 528, in open_connection
    conn_obj.open(
  File "/Users/evangoulden/.local/share/virtualenvs/nornir_netauto-sh27gIds/lib/python3.11/site-packages/nornir_napalm/plugins/connections/__init__.py", line 55, in open
    network_driver = get_network_driver(platform)
                     ^^^^^^^^^^^^^^^^^^^^^^^^^^^^
  File "/Users/evangoulden/.local/share/virtualenvs/nornir_netauto-sh27gIds/lib/python3.11/site-packages/napalm/base/__init__.py", line 70, in get_network_driver
    raise ModuleImportError("Please provide a valid driver name.")
napalm.base.exceptions.ModuleImportError: Please provide a valid driver name.

2025-03-15 22:02:29,419 - nornir.core.task -    ERROR -      start() - Host 'buildroom': task 'backup_config' failed with traceback:
Traceback (most recent call last):
  File "/Users/evangoulden/.local/share/virtualenvs/nornir_netauto-sh27gIds/lib/python3.11/site-packages/nornir/core/task.py", line 98, in start
    r = self.task(self, **self.params)
        ^^^^^^^^^^^^^^^^^^^^^^^^^^^^^^
  File "/Users/evangoulden/Code/nornir_netauto/netauto.py", line 19, in backup_config
    return task.run(task=napalm_get, getters=["config"])
           ^^^^^^^^^^^^^^^^^^^^^^^^^^^^^^^^^^^^^^^^^^^^^
  File "/Users/evangoulden/.local/share/virtualenvs/nornir_netauto-sh27gIds/lib/python3.11/site-packages/nornir/core/task.py", line 173, in run
    raise NornirSubTaskError(task=run_task, result=r)
nornir.core.exceptions.NornirSubTaskError: Subtask: napalm_get (failed)


2025-03-15 22:02:37,482 -  nornir.core -     INFO -        run() - Running task 'backup_config' with args {} on 1 hosts
2025-03-15 22:02:37,483 - nornir.core.task -    ERROR -      start() - Host 'buildroom': task 'napalm_get' failed with traceback:
Traceback (most recent call last):
  File "/Users/evangoulden/.local/share/virtualenvs/nornir_netauto-sh27gIds/lib/python3.11/site-packages/nornir/core/task.py", line 98, in start
    r = self.task(self, **self.params)
        ^^^^^^^^^^^^^^^^^^^^^^^^^^^^^^
  File "/Users/evangoulden/.local/share/virtualenvs/nornir_netauto-sh27gIds/lib/python3.11/site-packages/nornir_napalm/plugins/tasks/napalm_get.py", line 32, in napalm_get
    device = task.host.get_connection(CONNECTION_NAME, task.nornir.config)
             ^^^^^^^^^^^^^^^^^^^^^^^^^^^^^^^^^^^^^^^^^^^^^^^^^^^^^^^^^^^^^
  File "/Users/evangoulden/.local/share/virtualenvs/nornir_netauto-sh27gIds/lib/python3.11/site-packages/nornir/core/inventory.py", line 476, in get_connection
    self.open_connection(
  File "/Users/evangoulden/.local/share/virtualenvs/nornir_netauto-sh27gIds/lib/python3.11/site-packages/nornir/core/inventory.py", line 528, in open_connection
    conn_obj.open(
  File "/Users/evangoulden/.local/share/virtualenvs/nornir_netauto-sh27gIds/lib/python3.11/site-packages/nornir_napalm/plugins/connections/__init__.py", line 55, in open
    network_driver = get_network_driver(platform)
                     ^^^^^^^^^^^^^^^^^^^^^^^^^^^^
  File "/Users/evangoulden/.local/share/virtualenvs/nornir_netauto-sh27gIds/lib/python3.11/site-packages/napalm/base/__init__.py", line 70, in get_network_driver
    raise ModuleImportError("Please provide a valid driver name.")
napalm.base.exceptions.ModuleImportError: Please provide a valid driver name.

2025-03-15 22:02:37,483 - nornir.core.task -    ERROR -      start() - Host 'buildroom': task 'backup_config' failed with traceback:
Traceback (most recent call last):
  File "/Users/evangoulden/.local/share/virtualenvs/nornir_netauto-sh27gIds/lib/python3.11/site-packages/nornir/core/task.py", line 98, in start
    r = self.task(self, **self.params)
        ^^^^^^^^^^^^^^^^^^^^^^^^^^^^^^
  File "/Users/evangoulden/Code/nornir_netauto/netauto.py", line 19, in backup_config
    return task.run(task=napalm_get, getters=["config"])
           ^^^^^^^^^^^^^^^^^^^^^^^^^^^^^^^^^^^^^^^^^^^^^
  File "/Users/evangoulden/.local/share/virtualenvs/nornir_netauto-sh27gIds/lib/python3.11/site-packages/nornir/core/task.py", line 173, in run
    raise NornirSubTaskError(task=run_task, result=r)
nornir.core.exceptions.NornirSubTaskError: Subtask: napalm_get (failed)


2025-03-15 22:05:56,068 -  nornir.core -     INFO -        run() - Running task 'backup_config' with args {} on 1 hosts
2025-03-15 22:05:56,069 - nornir.core.task -    ERROR -      start() - Host 'buildroom': task 'napalm_get' failed with traceback:
Traceback (most recent call last):
  File "/Users/evangoulden/.local/share/virtualenvs/nornir_netauto-sh27gIds/lib/python3.11/site-packages/nornir/core/task.py", line 98, in start
    r = self.task(self, **self.params)
        ^^^^^^^^^^^^^^^^^^^^^^^^^^^^^^
  File "/Users/evangoulden/.local/share/virtualenvs/nornir_netauto-sh27gIds/lib/python3.11/site-packages/nornir_napalm/plugins/tasks/napalm_get.py", line 32, in napalm_get
    device = task.host.get_connection(CONNECTION_NAME, task.nornir.config)
             ^^^^^^^^^^^^^^^^^^^^^^^^^^^^^^^^^^^^^^^^^^^^^^^^^^^^^^^^^^^^^
  File "/Users/evangoulden/.local/share/virtualenvs/nornir_netauto-sh27gIds/lib/python3.11/site-packages/nornir/core/inventory.py", line 476, in get_connection
    self.open_connection(
  File "/Users/evangoulden/.local/share/virtualenvs/nornir_netauto-sh27gIds/lib/python3.11/site-packages/nornir/core/inventory.py", line 528, in open_connection
    conn_obj.open(
  File "/Users/evangoulden/.local/share/virtualenvs/nornir_netauto-sh27gIds/lib/python3.11/site-packages/nornir_napalm/plugins/connections/__init__.py", line 55, in open
    network_driver = get_network_driver(platform)
                     ^^^^^^^^^^^^^^^^^^^^^^^^^^^^
  File "/Users/evangoulden/.local/share/virtualenvs/nornir_netauto-sh27gIds/lib/python3.11/site-packages/napalm/base/__init__.py", line 70, in get_network_driver
    raise ModuleImportError("Please provide a valid driver name.")
napalm.base.exceptions.ModuleImportError: Please provide a valid driver name.

2025-03-15 22:05:56,069 - nornir.core.task -    ERROR -      start() - Host 'buildroom': task 'backup_config' failed with traceback:
Traceback (most recent call last):
  File "/Users/evangoulden/.local/share/virtualenvs/nornir_netauto-sh27gIds/lib/python3.11/site-packages/nornir/core/task.py", line 98, in start
    r = self.task(self, **self.params)
        ^^^^^^^^^^^^^^^^^^^^^^^^^^^^^^
  File "/Users/evangoulden/Code/nornir_netauto/netauto.py", line 19, in backup_config
    result = task.run(task=napalm_get, getters=["config"])
             ^^^^^^^^^^^^^^^^^^^^^^^^^^^^^^^^^^^^^^^^^^^^^
  File "/Users/evangoulden/.local/share/virtualenvs/nornir_netauto-sh27gIds/lib/python3.11/site-packages/nornir/core/task.py", line 173, in run
    raise NornirSubTaskError(task=run_task, result=r)
nornir.core.exceptions.NornirSubTaskError: Subtask: napalm_get (failed)


2025-03-15 22:06:19,236 -  nornir.core -     INFO -        run() - Running task 'backup_config' with args {} on 1 hosts
2025-03-15 22:06:19,237 - nornir.core.task -    ERROR -      start() - Host 'buildroom': task 'napalm_get' failed with traceback:
Traceback (most recent call last):
  File "/Users/evangoulden/.local/share/virtualenvs/nornir_netauto-sh27gIds/lib/python3.11/site-packages/nornir/core/task.py", line 98, in start
    r = self.task(self, **self.params)
        ^^^^^^^^^^^^^^^^^^^^^^^^^^^^^^
  File "/Users/evangoulden/.local/share/virtualenvs/nornir_netauto-sh27gIds/lib/python3.11/site-packages/nornir_napalm/plugins/tasks/napalm_get.py", line 32, in napalm_get
    device = task.host.get_connection(CONNECTION_NAME, task.nornir.config)
             ^^^^^^^^^^^^^^^^^^^^^^^^^^^^^^^^^^^^^^^^^^^^^^^^^^^^^^^^^^^^^
  File "/Users/evangoulden/.local/share/virtualenvs/nornir_netauto-sh27gIds/lib/python3.11/site-packages/nornir/core/inventory.py", line 476, in get_connection
    self.open_connection(
  File "/Users/evangoulden/.local/share/virtualenvs/nornir_netauto-sh27gIds/lib/python3.11/site-packages/nornir/core/inventory.py", line 528, in open_connection
    conn_obj.open(
  File "/Users/evangoulden/.local/share/virtualenvs/nornir_netauto-sh27gIds/lib/python3.11/site-packages/nornir_napalm/plugins/connections/__init__.py", line 55, in open
    network_driver = get_network_driver(platform)
                     ^^^^^^^^^^^^^^^^^^^^^^^^^^^^
  File "/Users/evangoulden/.local/share/virtualenvs/nornir_netauto-sh27gIds/lib/python3.11/site-packages/napalm/base/__init__.py", line 70, in get_network_driver
    raise ModuleImportError("Please provide a valid driver name.")
napalm.base.exceptions.ModuleImportError: Please provide a valid driver name.

2025-03-15 22:06:19,238 - nornir.core.task -    ERROR -      start() - Host 'buildroom': task 'backup_config' failed with traceback:
Traceback (most recent call last):
  File "/Users/evangoulden/.local/share/virtualenvs/nornir_netauto-sh27gIds/lib/python3.11/site-packages/nornir/core/task.py", line 98, in start
    r = self.task(self, **self.params)
        ^^^^^^^^^^^^^^^^^^^^^^^^^^^^^^
  File "/Users/evangoulden/Code/nornir_netauto/netauto.py", line 19, in backup_config
    result = task.run(task=napalm_get, getters=["config"])
             ^^^^^^^^^^^^^^^^^^^^^^^^^^^^^^^^^^^^^^^^^^^^^
  File "/Users/evangoulden/.local/share/virtualenvs/nornir_netauto-sh27gIds/lib/python3.11/site-packages/nornir/core/task.py", line 173, in run
    raise NornirSubTaskError(task=run_task, result=r)
nornir.core.exceptions.NornirSubTaskError: Subtask: napalm_get (failed)


2025-03-15 22:06:44,023 -  nornir.core -     INFO -        run() - Running task 'backup_config' with args {} on 1 hosts
2025-03-15 22:07:06,291 - nornir.core.task -    ERROR -      start() - Host 'buildroom': task 'napalm_get' failed with traceback:
Traceback (most recent call last):
  File "/Users/evangoulden/.local/share/virtualenvs/nornir_netauto-sh27gIds/lib/python3.11/site-packages/nornir/core/task.py", line 98, in start
    r = self.task(self, **self.params)
        ^^^^^^^^^^^^^^^^^^^^^^^^^^^^^^
  File "/Users/evangoulden/.local/share/virtualenvs/nornir_netauto-sh27gIds/lib/python3.11/site-packages/nornir_napalm/plugins/tasks/napalm_get.py", line 32, in napalm_get
    device = task.host.get_connection(CONNECTION_NAME, task.nornir.config)
             ^^^^^^^^^^^^^^^^^^^^^^^^^^^^^^^^^^^^^^^^^^^^^^^^^^^^^^^^^^^^^
  File "/Users/evangoulden/.local/share/virtualenvs/nornir_netauto-sh27gIds/lib/python3.11/site-packages/nornir/core/inventory.py", line 476, in get_connection
    self.open_connection(
  File "/Users/evangoulden/.local/share/virtualenvs/nornir_netauto-sh27gIds/lib/python3.11/site-packages/nornir/core/inventory.py", line 528, in open_connection
    conn_obj.open(
  File "/Users/evangoulden/.local/share/virtualenvs/nornir_netauto-sh27gIds/lib/python3.11/site-packages/nornir_napalm/plugins/connections/__init__.py", line 55, in open
    network_driver = get_network_driver(platform)
                     ^^^^^^^^^^^^^^^^^^^^^^^^^^^^
  File "/Users/evangoulden/.local/share/virtualenvs/nornir_netauto-sh27gIds/lib/python3.11/site-packages/napalm/base/__init__.py", line 70, in get_network_driver
    raise ModuleImportError("Please provide a valid driver name.")
napalm.base.exceptions.ModuleImportError: Please provide a valid driver name.

2025-03-15 22:08:32,777 -  nornir.core -     INFO -        run() - Running task 'backup_config' with args {} on 1 hosts
2025-03-15 22:08:34,403 - nornir.core.task -    ERROR -      start() - Host 'buildroom': task 'napalm_get' failed with traceback:
Traceback (most recent call last):
  File "/Users/evangoulden/.local/share/virtualenvs/nornir_netauto-sh27gIds/lib/python3.11/site-packages/nornir/core/task.py", line 98, in start
    r = self.task(self, **self.params)
        ^^^^^^^^^^^^^^^^^^^^^^^^^^^^^^
  File "/Users/evangoulden/.local/share/virtualenvs/nornir_netauto-sh27gIds/lib/python3.11/site-packages/nornir_napalm/plugins/tasks/napalm_get.py", line 32, in napalm_get
    device = task.host.get_connection(CONNECTION_NAME, task.nornir.config)
             ^^^^^^^^^^^^^^^^^^^^^^^^^^^^^^^^^^^^^^^^^^^^^^^^^^^^^^^^^^^^^
  File "/Users/evangoulden/.local/share/virtualenvs/nornir_netauto-sh27gIds/lib/python3.11/site-packages/nornir/core/inventory.py", line 476, in get_connection
    self.open_connection(
  File "/Users/evangoulden/.local/share/virtualenvs/nornir_netauto-sh27gIds/lib/python3.11/site-packages/nornir/core/inventory.py", line 528, in open_connection
    conn_obj.open(
  File "/Users/evangoulden/.local/share/virtualenvs/nornir_netauto-sh27gIds/lib/python3.11/site-packages/nornir_napalm/plugins/connections/__init__.py", line 57, in open
    connection.open()
  File "/Users/evangoulden/.local/share/virtualenvs/nornir_netauto-sh27gIds/lib/python3.11/site-packages/napalm/ios/ios.py", line 173, in open
    self.device = self._netmiko_open(
                  ^^^^^^^^^^^^^^^^^^^
  File "/Users/evangoulden/.local/share/virtualenvs/nornir_netauto-sh27gIds/lib/python3.11/site-packages/napalm/base/base.py", line 129, in _netmiko_open
    self._netmiko_device.enable()
  File "/Users/evangoulden/.local/share/virtualenvs/nornir_netauto-sh27gIds/lib/python3.11/site-packages/netmiko/cisco_base_connection.py", line 27, in enable
    return super().enable(
           ^^^^^^^^^^^^^^^
  File "/Users/evangoulden/.local/share/virtualenvs/nornir_netauto-sh27gIds/lib/python3.11/site-packages/netmiko/base_connection.py", line 2062, in enable
    raise ValueError(msg)
ValueError: Failed to enter enable mode. Please ensure you pass the 'secret' argument to ConnectHandler.

2025-03-15 22:08:34,403 - nornir.core.task -    ERROR -      start() - Host 'buildroom': task 'backup_config' failed with traceback:
Traceback (most recent call last):
  File "/Users/evangoulden/.local/share/virtualenvs/nornir_netauto-sh27gIds/lib/python3.11/site-packages/nornir/core/task.py", line 98, in start
    r = self.task(self, **self.params)
        ^^^^^^^^^^^^^^^^^^^^^^^^^^^^^^
  File "/Users/evangoulden/Code/nornir_netauto/netauto.py", line 19, in backup_config
    result = task.run(task=napalm_get, getters=["config"])
             ^^^^^^^^^^^^^^^^^^^^^^^^^^^^^^^^^^^^^^^^^^^^^
  File "/Users/evangoulden/.local/share/virtualenvs/nornir_netauto-sh27gIds/lib/python3.11/site-packages/nornir/core/task.py", line 173, in run
    raise NornirSubTaskError(task=run_task, result=r)
nornir.core.exceptions.NornirSubTaskError: Subtask: napalm_get (failed)


2025-03-15 22:09:22,685 -  nornir.core -     INFO -        run() - Running task 'backup_config' with args {} on 1 hosts
2025-03-15 22:09:24,278 - nornir.core.task -    ERROR -      start() - Host 'buildroom': task 'napalm_get' failed with traceback:
Traceback (most recent call last):
  File "/Users/evangoulden/.local/share/virtualenvs/nornir_netauto-sh27gIds/lib/python3.11/site-packages/nornir/core/task.py", line 98, in start
    r = self.task(self, **self.params)
        ^^^^^^^^^^^^^^^^^^^^^^^^^^^^^^
  File "/Users/evangoulden/.local/share/virtualenvs/nornir_netauto-sh27gIds/lib/python3.11/site-packages/nornir_napalm/plugins/tasks/napalm_get.py", line 32, in napalm_get
    device = task.host.get_connection(CONNECTION_NAME, task.nornir.config)
             ^^^^^^^^^^^^^^^^^^^^^^^^^^^^^^^^^^^^^^^^^^^^^^^^^^^^^^^^^^^^^
  File "/Users/evangoulden/.local/share/virtualenvs/nornir_netauto-sh27gIds/lib/python3.11/site-packages/nornir/core/inventory.py", line 476, in get_connection
    self.open_connection(
  File "/Users/evangoulden/.local/share/virtualenvs/nornir_netauto-sh27gIds/lib/python3.11/site-packages/nornir/core/inventory.py", line 528, in open_connection
    conn_obj.open(
  File "/Users/evangoulden/.local/share/virtualenvs/nornir_netauto-sh27gIds/lib/python3.11/site-packages/nornir_napalm/plugins/connections/__init__.py", line 57, in open
    connection.open()
  File "/Users/evangoulden/.local/share/virtualenvs/nornir_netauto-sh27gIds/lib/python3.11/site-packages/napalm/ios/ios.py", line 173, in open
    self.device = self._netmiko_open(
                  ^^^^^^^^^^^^^^^^^^^
  File "/Users/evangoulden/.local/share/virtualenvs/nornir_netauto-sh27gIds/lib/python3.11/site-packages/napalm/base/base.py", line 129, in _netmiko_open
    self._netmiko_device.enable()
  File "/Users/evangoulden/.local/share/virtualenvs/nornir_netauto-sh27gIds/lib/python3.11/site-packages/netmiko/cisco_base_connection.py", line 27, in enable
    return super().enable(
           ^^^^^^^^^^^^^^^
  File "/Users/evangoulden/.local/share/virtualenvs/nornir_netauto-sh27gIds/lib/python3.11/site-packages/netmiko/base_connection.py", line 2062, in enable
    raise ValueError(msg)
ValueError: Failed to enter enable mode. Please ensure you pass the 'secret' argument to ConnectHandler.

2025-03-15 22:09:24,279 - nornir.core.task -    ERROR -      start() - Host 'buildroom': task 'backup_config' failed with traceback:
Traceback (most recent call last):
  File "/Users/evangoulden/.local/share/virtualenvs/nornir_netauto-sh27gIds/lib/python3.11/site-packages/nornir/core/task.py", line 98, in start
    r = self.task(self, **self.params)
        ^^^^^^^^^^^^^^^^^^^^^^^^^^^^^^
  File "/Users/evangoulden/Code/nornir_netauto/netauto.py", line 19, in backup_config
    result = task.run(task=napalm_get, getters=["config"])
             ^^^^^^^^^^^^^^^^^^^^^^^^^^^^^^^^^^^^^^^^^^^^^
  File "/Users/evangoulden/.local/share/virtualenvs/nornir_netauto-sh27gIds/lib/python3.11/site-packages/nornir/core/task.py", line 173, in run
    raise NornirSubTaskError(task=run_task, result=r)
nornir.core.exceptions.NornirSubTaskError: Subtask: napalm_get (failed)


2025-03-15 22:11:15,854 -  nornir.core -     INFO -        run() - Running task 'backup_config' with args {} on 1 hosts
2025-03-15 22:11:17,432 - nornir.core.task -    ERROR -      start() - Host 'buildroom': task 'napalm_get' failed with traceback:
Traceback (most recent call last):
  File "/Users/evangoulden/.local/share/virtualenvs/nornir_netauto-sh27gIds/lib/python3.11/site-packages/nornir/core/task.py", line 98, in start
    r = self.task(self, **self.params)
        ^^^^^^^^^^^^^^^^^^^^^^^^^^^^^^
  File "/Users/evangoulden/.local/share/virtualenvs/nornir_netauto-sh27gIds/lib/python3.11/site-packages/nornir_napalm/plugins/tasks/napalm_get.py", line 32, in napalm_get
    device = task.host.get_connection(CONNECTION_NAME, task.nornir.config)
             ^^^^^^^^^^^^^^^^^^^^^^^^^^^^^^^^^^^^^^^^^^^^^^^^^^^^^^^^^^^^^
  File "/Users/evangoulden/.local/share/virtualenvs/nornir_netauto-sh27gIds/lib/python3.11/site-packages/nornir/core/inventory.py", line 476, in get_connection
    self.open_connection(
  File "/Users/evangoulden/.local/share/virtualenvs/nornir_netauto-sh27gIds/lib/python3.11/site-packages/nornir/core/inventory.py", line 528, in open_connection
    conn_obj.open(
  File "/Users/evangoulden/.local/share/virtualenvs/nornir_netauto-sh27gIds/lib/python3.11/site-packages/nornir_napalm/plugins/connections/__init__.py", line 57, in open
    connection.open()
  File "/Users/evangoulden/.local/share/virtualenvs/nornir_netauto-sh27gIds/lib/python3.11/site-packages/napalm/ios/ios.py", line 173, in open
    self.device = self._netmiko_open(
                  ^^^^^^^^^^^^^^^^^^^
  File "/Users/evangoulden/.local/share/virtualenvs/nornir_netauto-sh27gIds/lib/python3.11/site-packages/napalm/base/base.py", line 129, in _netmiko_open
    self._netmiko_device.enable()
  File "/Users/evangoulden/.local/share/virtualenvs/nornir_netauto-sh27gIds/lib/python3.11/site-packages/netmiko/cisco_base_connection.py", line 27, in enable
    return super().enable(
           ^^^^^^^^^^^^^^^
  File "/Users/evangoulden/.local/share/virtualenvs/nornir_netauto-sh27gIds/lib/python3.11/site-packages/netmiko/base_connection.py", line 2062, in enable
    raise ValueError(msg)
ValueError: Failed to enter enable mode. Please ensure you pass the 'secret' argument to ConnectHandler.

2025-03-15 22:11:17,433 - nornir.core.task -    ERROR -      start() - Host 'buildroom': task 'backup_config' failed with traceback:
Traceback (most recent call last):
  File "/Users/evangoulden/.local/share/virtualenvs/nornir_netauto-sh27gIds/lib/python3.11/site-packages/nornir/core/task.py", line 98, in start
    r = self.task(self, **self.params)
        ^^^^^^^^^^^^^^^^^^^^^^^^^^^^^^
  File "/Users/evangoulden/Code/nornir_netauto/netauto.py", line 19, in backup_config
    result = task.run(task=napalm_get, getters=["config"])
             ^^^^^^^^^^^^^^^^^^^^^^^^^^^^^^^^^^^^^^^^^^^^^
  File "/Users/evangoulden/.local/share/virtualenvs/nornir_netauto-sh27gIds/lib/python3.11/site-packages/nornir/core/task.py", line 173, in run
    raise NornirSubTaskError(task=run_task, result=r)
nornir.core.exceptions.NornirSubTaskError: Subtask: napalm_get (failed)


2025-03-15 22:13:48,680 -  nornir.core -     INFO -        run() - Running task 'backup_config' with args {} on 1 hosts
2025-03-15 22:15:43,463 -  nornir.core -     INFO -        run() - Running task 'backup_config' with args {} on 1 hosts
2025-03-15 22:18:09,616 -  nornir.core -     INFO -        run() - Running task 'backup_config' with args {} on 1 hosts
2025-03-15 22:18:27,203 - nornir.core.task -    ERROR -      start() - Host 'buildroom': task 'napalm_get' failed with traceback:
Traceback (most recent call last):
  File "/Users/evangoulden/.local/share/virtualenvs/nornir_netauto-sh27gIds/lib/python3.11/site-packages/nornir/core/task.py", line 98, in start
    r = self.task(self, **self.params)
        ^^^^^^^^^^^^^^^^^^^^^^^^^^^^^^
  File "/Users/evangoulden/.local/share/virtualenvs/nornir_netauto-sh27gIds/lib/python3.11/site-packages/nornir_napalm/plugins/tasks/napalm_get.py", line 32, in napalm_get
    device = task.host.get_connection(CONNECTION_NAME, task.nornir.config)
             ^^^^^^^^^^^^^^^^^^^^^^^^^^^^^^^^^^^^^^^^^^^^^^^^^^^^^^^^^^^^^
  File "/Users/evangoulden/.local/share/virtualenvs/nornir_netauto-sh27gIds/lib/python3.11/site-packages/nornir/core/inventory.py", line 476, in get_connection
    self.open_connection(
  File "/Users/evangoulden/.local/share/virtualenvs/nornir_netauto-sh27gIds/lib/python3.11/site-packages/nornir/core/inventory.py", line 528, in open_connection
    conn_obj.open(
  File "/Users/evangoulden/.local/share/virtualenvs/nornir_netauto-sh27gIds/lib/python3.11/site-packages/nornir_napalm/plugins/connections/__init__.py", line 56, in open
    connection = network_driver(**parameters)
                 ^^^^^^^^^^^^^^^^^^^^^^^^^^^^
TypeError: IOSDriver.__init__() got an unexpected keyword argument 'secret'

2025-03-15 22:18:34,606 -  nornir.core -     INFO -        run() - Running task 'backup_config' with args {} on 1 hosts
2025-03-15 22:18:34,607 - nornir.core.task -    ERROR -      start() - Host 'buildroom': task 'napalm_get' failed with traceback:
Traceback (most recent call last):
  File "/Users/evangoulden/.local/share/virtualenvs/nornir_netauto-sh27gIds/lib/python3.11/site-packages/nornir/core/task.py", line 98, in start
    r = self.task(self, **self.params)
        ^^^^^^^^^^^^^^^^^^^^^^^^^^^^^^
  File "/Users/evangoulden/.local/share/virtualenvs/nornir_netauto-sh27gIds/lib/python3.11/site-packages/nornir_napalm/plugins/tasks/napalm_get.py", line 32, in napalm_get
    device = task.host.get_connection(CONNECTION_NAME, task.nornir.config)
             ^^^^^^^^^^^^^^^^^^^^^^^^^^^^^^^^^^^^^^^^^^^^^^^^^^^^^^^^^^^^^
  File "/Users/evangoulden/.local/share/virtualenvs/nornir_netauto-sh27gIds/lib/python3.11/site-packages/nornir/core/inventory.py", line 476, in get_connection
    self.open_connection(
  File "/Users/evangoulden/.local/share/virtualenvs/nornir_netauto-sh27gIds/lib/python3.11/site-packages/nornir/core/inventory.py", line 528, in open_connection
    conn_obj.open(
  File "/Users/evangoulden/.local/share/virtualenvs/nornir_netauto-sh27gIds/lib/python3.11/site-packages/nornir_napalm/plugins/connections/__init__.py", line 56, in open
    connection = network_driver(**parameters)
                 ^^^^^^^^^^^^^^^^^^^^^^^^^^^^
TypeError: IOSDriver.__init__() got an unexpected keyword argument 'secret'

2025-03-15 22:18:34,607 - nornir.core.task -    ERROR -      start() - Host 'buildroom': task 'backup_config' failed with traceback:
Traceback (most recent call last):
  File "/Users/evangoulden/.local/share/virtualenvs/nornir_netauto-sh27gIds/lib/python3.11/site-packages/nornir/core/task.py", line 98, in start
    r = self.task(self, **self.params)
        ^^^^^^^^^^^^^^^^^^^^^^^^^^^^^^
  File "/Users/evangoulden/Code/nornir_netauto/netauto.py", line 19, in backup_config
    result = task.run(task=napalm_get, getters=["config"])
             ^^^^^^^^^^^^^^^^^^^^^^^^^^^^^^^^^^^^^^^^^^^^^
  File "/Users/evangoulden/.local/share/virtualenvs/nornir_netauto-sh27gIds/lib/python3.11/site-packages/nornir/core/task.py", line 173, in run
    raise NornirSubTaskError(task=run_task, result=r)
nornir.core.exceptions.NornirSubTaskError: Subtask: napalm_get (failed)


2025-03-15 22:19:01,878 -  nornir.core -     INFO -        run() - Running task 'backup_config' with args {} on 1 hosts
2025-03-15 22:19:28,759 - nornir.core.task -    ERROR -      start() - Host 'buildroom': task 'napalm_get' failed with traceback:
Traceback (most recent call last):
  File "/Users/evangoulden/.local/share/virtualenvs/nornir_netauto-sh27gIds/lib/python3.11/site-packages/nornir/core/task.py", line 98, in start
    r = self.task(self, **self.params)
        ^^^^^^^^^^^^^^^^^^^^^^^^^^^^^^
  File "/Users/evangoulden/.local/share/virtualenvs/nornir_netauto-sh27gIds/lib/python3.11/site-packages/nornir_napalm/plugins/tasks/napalm_get.py", line 32, in napalm_get
    device = task.host.get_connection(CONNECTION_NAME, task.nornir.config)
             ^^^^^^^^^^^^^^^^^^^^^^^^^^^^^^^^^^^^^^^^^^^^^^^^^^^^^^^^^^^^^
  File "/Users/evangoulden/.local/share/virtualenvs/nornir_netauto-sh27gIds/lib/python3.11/site-packages/nornir/core/inventory.py", line 476, in get_connection
    self.open_connection(
  File "/Users/evangoulden/.local/share/virtualenvs/nornir_netauto-sh27gIds/lib/python3.11/site-packages/nornir/core/inventory.py", line 528, in open_connection
    conn_obj.open(
  File "/Users/evangoulden/.local/share/virtualenvs/nornir_netauto-sh27gIds/lib/python3.11/site-packages/nornir_napalm/plugins/connections/__init__.py", line 56, in open
    connection = network_driver(**parameters)
                 ^^^^^^^^^^^^^^^^^^^^^^^^^^^^
TypeError: IOSDriver.__init__() got an unexpected keyword argument 'secret'

2025-03-15 22:19:28,760 - nornir.core.task -    ERROR -      start() - Host 'buildroom': task 'backup_config' failed with traceback:
Traceback (most recent call last):
  File "/Users/evangoulden/.local/share/virtualenvs/nornir_netauto-sh27gIds/lib/python3.11/site-packages/nornir/core/task.py", line 98, in start
    r = self.task(self, **self.params)
        ^^^^^^^^^^^^^^^^^^^^^^^^^^^^^^
  File "/Users/evangoulden/Code/nornir_netauto/netauto.py", line 19, in backup_config
    result = task.run(task=napalm_get, getters=["config"])
             ^^^^^^^^^^^^^^^^^^^^^^^^^^^^^^^^^^^^^^^^^^^^^
  File "/Users/evangoulden/.local/share/virtualenvs/nornir_netauto-sh27gIds/lib/python3.11/site-packages/nornir/core/task.py", line 173, in run
    raise NornirSubTaskError(task=run_task, result=r)
nornir.core.exceptions.NornirSubTaskError: Subtask: napalm_get (failed)


2025-03-15 22:19:42,853 -  nornir.core -     INFO -        run() - Running task 'backup_config' with args {} on 1 hosts
2025-03-15 22:19:42,854 - nornir.core.task -    ERROR -      start() - Host 'buildroom': task 'napalm_get' failed with traceback:
Traceback (most recent call last):
  File "/Users/evangoulden/.local/share/virtualenvs/nornir_netauto-sh27gIds/lib/python3.11/site-packages/nornir/core/task.py", line 98, in start
    r = self.task(self, **self.params)
        ^^^^^^^^^^^^^^^^^^^^^^^^^^^^^^
  File "/Users/evangoulden/.local/share/virtualenvs/nornir_netauto-sh27gIds/lib/python3.11/site-packages/nornir_napalm/plugins/tasks/napalm_get.py", line 32, in napalm_get
    device = task.host.get_connection(CONNECTION_NAME, task.nornir.config)
             ^^^^^^^^^^^^^^^^^^^^^^^^^^^^^^^^^^^^^^^^^^^^^^^^^^^^^^^^^^^^^
  File "/Users/evangoulden/.local/share/virtualenvs/nornir_netauto-sh27gIds/lib/python3.11/site-packages/nornir/core/inventory.py", line 476, in get_connection
    self.open_connection(
  File "/Users/evangoulden/.local/share/virtualenvs/nornir_netauto-sh27gIds/lib/python3.11/site-packages/nornir/core/inventory.py", line 528, in open_connection
    conn_obj.open(
  File "/Users/evangoulden/.local/share/virtualenvs/nornir_netauto-sh27gIds/lib/python3.11/site-packages/nornir_napalm/plugins/connections/__init__.py", line 56, in open
    connection = network_driver(**parameters)
                 ^^^^^^^^^^^^^^^^^^^^^^^^^^^^
TypeError: IOSDriver.__init__() got an unexpected keyword argument 'secret'

2025-03-15 22:19:42,854 - nornir.core.task -    ERROR -      start() - Host 'buildroom': task 'backup_config' failed with traceback:
Traceback (most recent call last):
  File "/Users/evangoulden/.local/share/virtualenvs/nornir_netauto-sh27gIds/lib/python3.11/site-packages/nornir/core/task.py", line 98, in start
    r = self.task(self, **self.params)
        ^^^^^^^^^^^^^^^^^^^^^^^^^^^^^^
  File "/Users/evangoulden/Code/nornir_netauto/netauto.py", line 19, in backup_config
    result = task.run(task=napalm_get, getters=["config"])
             ^^^^^^^^^^^^^^^^^^^^^^^^^^^^^^^^^^^^^^^^^^^^^
  File "/Users/evangoulden/.local/share/virtualenvs/nornir_netauto-sh27gIds/lib/python3.11/site-packages/nornir/core/task.py", line 173, in run
    raise NornirSubTaskError(task=run_task, result=r)
nornir.core.exceptions.NornirSubTaskError: Subtask: napalm_get (failed)


2025-03-15 22:21:24,095 -  nornir.core -     INFO -        run() - Running task 'backup_config' with args {} on 1 hosts
2025-03-17 09:35:44,609 -  nornir.core -     INFO -        run() - Running task 'backup_config' with args {} on 1 hosts
2025-03-17 09:35:44,610 - nornir.core.task -    ERROR -      start() - Host 'buildroom': task 'backup_config' failed with traceback:
Traceback (most recent call last):
  File "/Users/evangoulden/.local/share/virtualenvs/nornir_netauto-sh27gIds/lib/python3.11/site-packages/nornir/core/task.py", line 98, in start
    r = self.task(self, **self.params)
        ^^^^^^^^^^^^^^^^^^^^^^^^^^^^^^
  File "/Users/evangoulden/Code/nornir_netauto/netauto.py", line 21, in backup_config
    raise ValueError("No secret set for device")
ValueError: No secret set for device

2025-03-17 09:38:39,420 -  nornir.core -     INFO -        run() - Running task 'backup_config' with args {} on 1 hosts
2025-03-17 09:38:39,423 - nornir.core.task -    ERROR -      start() - Host 'buildroom': task 'backup_config' failed with traceback:
Traceback (most recent call last):
  File "/Users/evangoulden/.local/share/virtualenvs/nornir_netauto-sh27gIds/lib/python3.11/site-packages/nornir/core/task.py", line 98, in start
    r = self.task(self, **self.params)
        ^^^^^^^^^^^^^^^^^^^^^^^^^^^^^^
  File "/Users/evangoulden/Code/nornir_netauto/netauto.py", line 21, in backup_config
    raise ValueError("No secret set for device")
ValueError: No secret set for device

2025-03-17 09:38:52,366 -  nornir.core -     INFO -        run() - Running task 'backup_config' with args {} on 1 hosts
2025-03-17 09:38:52,368 - nornir.core.task -    ERROR -      start() - Host 'buildroom': task 'backup_config' failed with traceback:
Traceback (most recent call last):
  File "/Users/evangoulden/.local/share/virtualenvs/nornir_netauto-sh27gIds/lib/python3.11/site-packages/nornir/core/task.py", line 98, in start
    r = self.task(self, **self.params)
        ^^^^^^^^^^^^^^^^^^^^^^^^^^^^^^
  File "/Users/evangoulden/Code/nornir_netauto/netauto.py", line 21, in backup_config
    raise ValueError("No secret set for device")
ValueError: No secret set for device

2025-03-17 09:39:15,715 -  nornir.core -     INFO -        run() - Running task 'backup_config' with args {} on 1 hosts
2025-03-17 09:43:49,619 -  nornir.core -     INFO -        run() - Running task 'backup_config' with args {} on 1 hosts
2025-03-17 09:44:44,921 - nornir.core.task -    ERROR -      start() - Host 'buildroom': task 'backup_config' failed with traceback:
Traceback (most recent call last):
  File "/Users/evangoulden/.local/share/virtualenvs/nornir_netauto-sh27gIds/lib/python3.11/site-packages/nornir/core/task.py", line 98, in start
    r = self.task(self, **self.params)
        ^^^^^^^^^^^^^^^^^^^^^^^^^^^^^^
  File "/Users/evangoulden/Code/nornir_netauto/netauto.py", line 22, in backup_config
    raise ValueError("No secret set for device")
ValueError: No secret set for device

2025-03-17 09:50:01,544 -  nornir.core -     INFO -        run() - Running task 'backup_config' with args {} on 1 hosts
2025-03-17 09:50:01,545 - nornir.core.task -    ERROR -      start() - Host 'buildroom': task 'backup_config' failed with traceback:
Traceback (most recent call last):
  File "/Users/evangoulden/.local/share/virtualenvs/nornir_netauto-sh27gIds/lib/python3.11/site-packages/nornir/core/task.py", line 98, in start
    r = self.task(self, **self.params)
        ^^^^^^^^^^^^^^^^^^^^^^^^^^^^^^
  File "/Users/evangoulden/Code/nornir_netauto/netauto.py", line 22, in backup_config
    raise ValueError("No secret set for device")
ValueError: No secret set for device

2025-03-17 09:51:11,900 -  nornir.core -     INFO -        run() - Running task 'backup_config' with args {} on 1 hosts
2025-03-17 09:51:32,658 -  nornir.core -     INFO -        run() - Running task 'backup_config' with args {} on 1 hosts
2025-03-17 09:52:55,863 -  nornir.core -     INFO -        run() - Running task 'backup_config' with args {} on 1 hosts
2025-03-17 09:53:12,982 -  nornir.core -     INFO -        run() - Running task 'backup_config' with args {} on 1 hosts
2025-03-17 09:53:12,982 - nornir.core.task -    ERROR -      start() - Host 'buildroom': task 'backup_config' failed with traceback:
Traceback (most recent call last):
  File "/Users/evangoulden/.local/share/virtualenvs/nornir_netauto-sh27gIds/lib/python3.11/site-packages/nornir/core/task.py", line 98, in start
    r = self.task(self, **self.params)
        ^^^^^^^^^^^^^^^^^^^^^^^^^^^^^^
  File "/Users/evangoulden/Code/nornir_netauto/netauto.py", line 23, in backup_config
    task.host.connection_options["napalm"].extras["optional_args"]["secret"] = secret
    ~~~~~~~~~~~~~~~~~~~~~~~~~~~~^^^^^^^^^^
KeyError: 'napalm'

2025-03-17 09:53:42,122 -  nornir.core -     INFO -        run() - Running task 'backup_config' with args {} on 1 hosts
2025-03-17 09:55:05,484 -  nornir.core -     INFO -        run() - Running task 'backup_config' with args {} on 1 hosts
2025-03-17 09:55:05,484 - nornir.core.task -    ERROR -      start() - Host 'buildroom': task 'backup_config' failed with traceback:
Traceback (most recent call last):
  File "/Users/evangoulden/.local/share/virtualenvs/nornir_netauto-sh27gIds/lib/python3.11/site-packages/nornir/core/task.py", line 98, in start
    r = self.task(self, **self.params)
        ^^^^^^^^^^^^^^^^^^^^^^^^^^^^^^
  File "/Users/evangoulden/Code/nornir_netauto/netauto.py", line 23, in backup_config
    task.host.connection_options["napalm"]['extras']["optional_args"]["secret"] = secret
    ~~~~~~~~~~~~~~~~~~~~~~~~~~~~^^^^^^^^^^
KeyError: 'napalm'

2025-03-17 09:55:40,352 -  nornir.core -     INFO -        run() - Running task 'backup_config' with args {} on 1 hosts
2025-03-17 09:55:47,104 - nornir.core.task -    ERROR -      start() - Host 'buildroom': task 'napalm_get' failed with traceback:
Traceback (most recent call last):
  File "/Users/evangoulden/.local/share/virtualenvs/nornir_netauto-sh27gIds/lib/python3.11/site-packages/nornir/core/task.py", line 98, in start
    r = self.task(self, **self.params)
        ^^^^^^^^^^^^^^^^^^^^^^^^^^^^^^
  File "/Users/evangoulden/.local/share/virtualenvs/nornir_netauto-sh27gIds/lib/python3.11/site-packages/nornir_napalm/plugins/tasks/napalm_get.py", line 32, in napalm_get
    device = task.host.get_connection(CONNECTION_NAME, task.nornir.config)
             ^^^^^^^^^^^^^^^^^^^^^^^^^^^^^^^^^^^^^^^^^^^^^^^^^^^^^^^^^^^^^
  File "/Users/evangoulden/.local/share/virtualenvs/nornir_netauto-sh27gIds/lib/python3.11/site-packages/nornir/core/inventory.py", line 476, in get_connection
    self.open_connection(
  File "/Users/evangoulden/.local/share/virtualenvs/nornir_netauto-sh27gIds/lib/python3.11/site-packages/nornir/core/inventory.py", line 528, in open_connection
    conn_obj.open(
  File "/Users/evangoulden/.local/share/virtualenvs/nornir_netauto-sh27gIds/lib/python3.11/site-packages/nornir_napalm/plugins/connections/__init__.py", line 57, in open
    connection.open()
  File "/Users/evangoulden/.local/share/virtualenvs/nornir_netauto-sh27gIds/lib/python3.11/site-packages/napalm/ios/ios.py", line 173, in open
    self.device = self._netmiko_open(
                  ^^^^^^^^^^^^^^^^^^^
  File "/Users/evangoulden/.local/share/virtualenvs/nornir_netauto-sh27gIds/lib/python3.11/site-packages/napalm/base/base.py", line 129, in _netmiko_open
    self._netmiko_device.enable()
  File "/Users/evangoulden/.local/share/virtualenvs/nornir_netauto-sh27gIds/lib/python3.11/site-packages/netmiko/cisco_base_connection.py", line 27, in enable
    return super().enable(
           ^^^^^^^^^^^^^^^
  File "/Users/evangoulden/.local/share/virtualenvs/nornir_netauto-sh27gIds/lib/python3.11/site-packages/netmiko/base_connection.py", line 2062, in enable
    raise ValueError(msg)
ValueError: Failed to enter enable mode. Please ensure you pass the 'secret' argument to ConnectHandler.

2025-03-17 09:55:47,105 - nornir.core.task -    ERROR -      start() - Host 'buildroom': task 'backup_config' failed with traceback:
Traceback (most recent call last):
  File "/Users/evangoulden/.local/share/virtualenvs/nornir_netauto-sh27gIds/lib/python3.11/site-packages/nornir/core/task.py", line 98, in start
    r = self.task(self, **self.params)
        ^^^^^^^^^^^^^^^^^^^^^^^^^^^^^^
  File "/Users/evangoulden/Code/nornir_netauto/netauto.py", line 24, in backup_config
    result = task.run(task=napalm_get, getters=["config"])
             ^^^^^^^^^^^^^^^^^^^^^^^^^^^^^^^^^^^^^^^^^^^^^
  File "/Users/evangoulden/.local/share/virtualenvs/nornir_netauto-sh27gIds/lib/python3.11/site-packages/nornir/core/task.py", line 173, in run
    raise NornirSubTaskError(task=run_task, result=r)
nornir.core.exceptions.NornirSubTaskError: Subtask: napalm_get (failed)


2025-03-17 09:57:10,703 -  nornir.core -     INFO -        run() - Running task 'backup_config' with args {} on 1 hosts
2025-03-17 09:57:37,155 -  nornir.core -     INFO -        run() - Running task 'backup_config' with args {} on 1 hosts
2025-03-17 09:57:38,720 - nornir.core.task -    ERROR -      start() - Host 'buildroom': task 'napalm_get' failed with traceback:
Traceback (most recent call last):
  File "/Users/evangoulden/.local/share/virtualenvs/nornir_netauto-sh27gIds/lib/python3.11/site-packages/nornir/core/task.py", line 98, in start
    r = self.task(self, **self.params)
        ^^^^^^^^^^^^^^^^^^^^^^^^^^^^^^
  File "/Users/evangoulden/.local/share/virtualenvs/nornir_netauto-sh27gIds/lib/python3.11/site-packages/nornir_napalm/plugins/tasks/napalm_get.py", line 32, in napalm_get
    device = task.host.get_connection(CONNECTION_NAME, task.nornir.config)
             ^^^^^^^^^^^^^^^^^^^^^^^^^^^^^^^^^^^^^^^^^^^^^^^^^^^^^^^^^^^^^
  File "/Users/evangoulden/.local/share/virtualenvs/nornir_netauto-sh27gIds/lib/python3.11/site-packages/nornir/core/inventory.py", line 476, in get_connection
    self.open_connection(
  File "/Users/evangoulden/.local/share/virtualenvs/nornir_netauto-sh27gIds/lib/python3.11/site-packages/nornir/core/inventory.py", line 528, in open_connection
    conn_obj.open(
  File "/Users/evangoulden/.local/share/virtualenvs/nornir_netauto-sh27gIds/lib/python3.11/site-packages/nornir_napalm/plugins/connections/__init__.py", line 57, in open
    connection.open()
  File "/Users/evangoulden/.local/share/virtualenvs/nornir_netauto-sh27gIds/lib/python3.11/site-packages/napalm/ios/ios.py", line 173, in open
    self.device = self._netmiko_open(
                  ^^^^^^^^^^^^^^^^^^^
  File "/Users/evangoulden/.local/share/virtualenvs/nornir_netauto-sh27gIds/lib/python3.11/site-packages/napalm/base/base.py", line 129, in _netmiko_open
    self._netmiko_device.enable()
  File "/Users/evangoulden/.local/share/virtualenvs/nornir_netauto-sh27gIds/lib/python3.11/site-packages/netmiko/cisco_base_connection.py", line 27, in enable
    return super().enable(
           ^^^^^^^^^^^^^^^
  File "/Users/evangoulden/.local/share/virtualenvs/nornir_netauto-sh27gIds/lib/python3.11/site-packages/netmiko/base_connection.py", line 2062, in enable
    raise ValueError(msg)
ValueError: Failed to enter enable mode. Please ensure you pass the 'secret' argument to ConnectHandler.

2025-03-17 09:57:38,722 - nornir.core.task -    ERROR -      start() - Host 'buildroom': task 'backup_config' failed with traceback:
Traceback (most recent call last):
  File "/Users/evangoulden/.local/share/virtualenvs/nornir_netauto-sh27gIds/lib/python3.11/site-packages/nornir/core/task.py", line 98, in start
    r = self.task(self, **self.params)
        ^^^^^^^^^^^^^^^^^^^^^^^^^^^^^^
  File "/Users/evangoulden/Code/nornir_netauto/netauto.py", line 24, in backup_config
    result = task.run(task=napalm_get, getters=["config"])
             ^^^^^^^^^^^^^^^^^^^^^^^^^^^^^^^^^^^^^^^^^^^^^
  File "/Users/evangoulden/.local/share/virtualenvs/nornir_netauto-sh27gIds/lib/python3.11/site-packages/nornir/core/task.py", line 173, in run
    raise NornirSubTaskError(task=run_task, result=r)
nornir.core.exceptions.NornirSubTaskError: Subtask: napalm_get (failed)


2025-03-17 09:58:32,523 -  nornir.core -     INFO -        run() - Running task 'backup_config' with args {} on 1 hosts
2025-03-17 09:58:34,256 - nornir.core.task -    ERROR -      start() - Host 'buildroom': task 'napalm_get' failed with traceback:
Traceback (most recent call last):
  File "/Users/evangoulden/.local/share/virtualenvs/nornir_netauto-sh27gIds/lib/python3.11/site-packages/nornir/core/task.py", line 98, in start
    r = self.task(self, **self.params)
        ^^^^^^^^^^^^^^^^^^^^^^^^^^^^^^
  File "/Users/evangoulden/.local/share/virtualenvs/nornir_netauto-sh27gIds/lib/python3.11/site-packages/nornir_napalm/plugins/tasks/napalm_get.py", line 32, in napalm_get
    device = task.host.get_connection(CONNECTION_NAME, task.nornir.config)
             ^^^^^^^^^^^^^^^^^^^^^^^^^^^^^^^^^^^^^^^^^^^^^^^^^^^^^^^^^^^^^
  File "/Users/evangoulden/.local/share/virtualenvs/nornir_netauto-sh27gIds/lib/python3.11/site-packages/nornir/core/inventory.py", line 476, in get_connection
    self.open_connection(
  File "/Users/evangoulden/.local/share/virtualenvs/nornir_netauto-sh27gIds/lib/python3.11/site-packages/nornir/core/inventory.py", line 528, in open_connection
    conn_obj.open(
  File "/Users/evangoulden/.local/share/virtualenvs/nornir_netauto-sh27gIds/lib/python3.11/site-packages/nornir_napalm/plugins/connections/__init__.py", line 57, in open
    connection.open()
  File "/Users/evangoulden/.local/share/virtualenvs/nornir_netauto-sh27gIds/lib/python3.11/site-packages/napalm/ios/ios.py", line 173, in open
    self.device = self._netmiko_open(
                  ^^^^^^^^^^^^^^^^^^^
  File "/Users/evangoulden/.local/share/virtualenvs/nornir_netauto-sh27gIds/lib/python3.11/site-packages/napalm/base/base.py", line 129, in _netmiko_open
    self._netmiko_device.enable()
  File "/Users/evangoulden/.local/share/virtualenvs/nornir_netauto-sh27gIds/lib/python3.11/site-packages/netmiko/cisco_base_connection.py", line 27, in enable
    return super().enable(
           ^^^^^^^^^^^^^^^
  File "/Users/evangoulden/.local/share/virtualenvs/nornir_netauto-sh27gIds/lib/python3.11/site-packages/netmiko/base_connection.py", line 2062, in enable
    raise ValueError(msg)
ValueError: Failed to enter enable mode. Please ensure you pass the 'secret' argument to ConnectHandler.

2025-03-17 09:58:34,257 - nornir.core.task -    ERROR -      start() - Host 'buildroom': task 'backup_config' failed with traceback:
Traceback (most recent call last):
  File "/Users/evangoulden/.local/share/virtualenvs/nornir_netauto-sh27gIds/lib/python3.11/site-packages/nornir/core/task.py", line 98, in start
    r = self.task(self, **self.params)
        ^^^^^^^^^^^^^^^^^^^^^^^^^^^^^^
  File "/Users/evangoulden/Code/nornir_netauto/netauto.py", line 24, in backup_config
    result = task.run(task=napalm_get, getters=["config"])
             ^^^^^^^^^^^^^^^^^^^^^^^^^^^^^^^^^^^^^^^^^^^^^
  File "/Users/evangoulden/.local/share/virtualenvs/nornir_netauto-sh27gIds/lib/python3.11/site-packages/nornir/core/task.py", line 173, in run
    raise NornirSubTaskError(task=run_task, result=r)
nornir.core.exceptions.NornirSubTaskError: Subtask: napalm_get (failed)


2025-03-17 10:10:06,945 -  nornir.core -     INFO -        run() - Running task 'backup_config' with args {} on 1 hosts
2025-03-17 10:10:44,058 -  nornir.core -     INFO -        run() - Running task 'backup_config' with args {} on 1 hosts
2025-03-17 10:24:06,629 -  nornir.core -     INFO -        run() - Running task 'backup_config' with args {} on 1 hosts
2025-03-17 10:24:34,371 -  nornir.core -     INFO -        run() - Running task 'backup_config' with args {} on 1 hosts
2025-03-17 10:25:55,694 -  nornir.core -     INFO -        run() - Running task 'backup_config' with args {} on 1 hosts
2025-03-17 11:54:41,591 -  nornir.core -     INFO -        run() - Running task 'backup_config' with args {} on 2 hosts
2025-03-17 11:56:10,453 -  nornir.core -     INFO -        run() - Running task 'backup_config' with args {} on 2 hosts
2025-03-17 12:06:27,452 -  nornir.core -     INFO -        run() - Running task 'backup_config' with args {} on 2 hosts
2025-03-17 14:02:05,648 -  nornir.core -     INFO -        run() - Running task 'backup_config' with args {} on 2 hosts
2025-03-18 10:09:31,297 -  nornir.core -     INFO -        run() - Running task 'backup_config' with args {} on 3 hosts
2025-03-18 10:09:41,353 - nornir.core.task -    ERROR -      start() - Host 'fg-core-3850': task 'napalm_get' failed with traceback:
Traceback (most recent call last):
  File "/Users/evangoulden/.local/share/virtualenvs/nornir_netauto-sh27gIds/lib/python3.11/site-packages/netmiko/base_connection.py", line 1142, in establish_connection
    self.remote_conn_pre.connect(**ssh_connect_params)
  File "/Users/evangoulden/.local/share/virtualenvs/nornir_netauto-sh27gIds/lib/python3.11/site-packages/paramiko/client.py", line 386, in connect
    sock.connect(addr)
TimeoutError: timed out

During handling of the above exception, another exception occurred:

Traceback (most recent call last):
  File "/Users/evangoulden/.local/share/virtualenvs/nornir_netauto-sh27gIds/lib/python3.11/site-packages/napalm/base/base.py", line 114, in _netmiko_open
    self._netmiko_device = ConnectHandler(
                           ^^^^^^^^^^^^^^^
  File "/Users/evangoulden/.local/share/virtualenvs/nornir_netauto-sh27gIds/lib/python3.11/site-packages/netmiko/ssh_dispatcher.py", line 410, in ConnectHandler
    return ConnectionClass(*args, **kwargs)
           ^^^^^^^^^^^^^^^^^^^^^^^^^^^^^^^^
  File "/Users/evangoulden/.local/share/virtualenvs/nornir_netauto-sh27gIds/lib/python3.11/site-packages/netmiko/base_connection.py", line 493, in __init__
    self._open()
  File "/Users/evangoulden/.local/share/virtualenvs/nornir_netauto-sh27gIds/lib/python3.11/site-packages/netmiko/base_connection.py", line 498, in _open
    self.establish_connection()
  File "/Users/evangoulden/.local/share/virtualenvs/nornir_netauto-sh27gIds/lib/python3.11/site-packages/netmiko/base_connection.py", line 1164, in establish_connection
    raise NetmikoTimeoutException(msg)
netmiko.exceptions.NetmikoTimeoutException: TCP connection to device failed.

Common causes of this problem are:
1. Incorrect hostname or IP address.
2. Wrong TCP port.
3. Intermediate firewall blocking access.

Device settings: cisco_ios 10.141.14.1:22



During handling of the above exception, another exception occurred:

Traceback (most recent call last):
  File "/Users/evangoulden/.local/share/virtualenvs/nornir_netauto-sh27gIds/lib/python3.11/site-packages/nornir/core/task.py", line 98, in start
    r = self.task(self, **self.params)
        ^^^^^^^^^^^^^^^^^^^^^^^^^^^^^^
  File "/Users/evangoulden/.local/share/virtualenvs/nornir_netauto-sh27gIds/lib/python3.11/site-packages/nornir_napalm/plugins/tasks/napalm_get.py", line 32, in napalm_get
    device = task.host.get_connection(CONNECTION_NAME, task.nornir.config)
             ^^^^^^^^^^^^^^^^^^^^^^^^^^^^^^^^^^^^^^^^^^^^^^^^^^^^^^^^^^^^^
  File "/Users/evangoulden/.local/share/virtualenvs/nornir_netauto-sh27gIds/lib/python3.11/site-packages/nornir/core/inventory.py", line 476, in get_connection
    self.open_connection(
  File "/Users/evangoulden/.local/share/virtualenvs/nornir_netauto-sh27gIds/lib/python3.11/site-packages/nornir/core/inventory.py", line 528, in open_connection
    conn_obj.open(
  File "/Users/evangoulden/.local/share/virtualenvs/nornir_netauto-sh27gIds/lib/python3.11/site-packages/nornir_napalm/plugins/connections/__init__.py", line 57, in open
    connection.open()
  File "/Users/evangoulden/.local/share/virtualenvs/nornir_netauto-sh27gIds/lib/python3.11/site-packages/napalm/ios/ios.py", line 173, in open
    self.device = self._netmiko_open(
                  ^^^^^^^^^^^^^^^^^^^
  File "/Users/evangoulden/.local/share/virtualenvs/nornir_netauto-sh27gIds/lib/python3.11/site-packages/napalm/base/base.py", line 123, in _netmiko_open
    raise ConnectionException("Cannot connect to {}".format(self.hostname))
napalm.base.exceptions.ConnectionException: Cannot connect to 10.141.14.1

2025-03-18 10:09:41,354 - nornir.core.task -    ERROR -      start() - Host 'buildroom': task 'napalm_get' failed with traceback:
Traceback (most recent call last):
  File "/Users/evangoulden/.local/share/virtualenvs/nornir_netauto-sh27gIds/lib/python3.11/site-packages/netmiko/base_connection.py", line 1142, in establish_connection
    self.remote_conn_pre.connect(**ssh_connect_params)
  File "/Users/evangoulden/.local/share/virtualenvs/nornir_netauto-sh27gIds/lib/python3.11/site-packages/paramiko/client.py", line 386, in connect
    sock.connect(addr)
TimeoutError: timed out

During handling of the above exception, another exception occurred:

Traceback (most recent call last):
  File "/Users/evangoulden/.local/share/virtualenvs/nornir_netauto-sh27gIds/lib/python3.11/site-packages/napalm/base/base.py", line 114, in _netmiko_open
    self._netmiko_device = ConnectHandler(
                           ^^^^^^^^^^^^^^^
  File "/Users/evangoulden/.local/share/virtualenvs/nornir_netauto-sh27gIds/lib/python3.11/site-packages/netmiko/ssh_dispatcher.py", line 410, in ConnectHandler
    return ConnectionClass(*args, **kwargs)
           ^^^^^^^^^^^^^^^^^^^^^^^^^^^^^^^^
  File "/Users/evangoulden/.local/share/virtualenvs/nornir_netauto-sh27gIds/lib/python3.11/site-packages/netmiko/base_connection.py", line 493, in __init__
    self._open()
  File "/Users/evangoulden/.local/share/virtualenvs/nornir_netauto-sh27gIds/lib/python3.11/site-packages/netmiko/base_connection.py", line 498, in _open
    self.establish_connection()
  File "/Users/evangoulden/.local/share/virtualenvs/nornir_netauto-sh27gIds/lib/python3.11/site-packages/netmiko/base_connection.py", line 1164, in establish_connection
    raise NetmikoTimeoutException(msg)
netmiko.exceptions.NetmikoTimeoutException: TCP connection to device failed.

Common causes of this problem are:
1. Incorrect hostname or IP address.
2. Wrong TCP port.
3. Intermediate firewall blocking access.

Device settings: cisco_ios 10.139.2.19:22



During handling of the above exception, another exception occurred:

Traceback (most recent call last):
  File "/Users/evangoulden/.local/share/virtualenvs/nornir_netauto-sh27gIds/lib/python3.11/site-packages/nornir/core/task.py", line 98, in start
    r = self.task(self, **self.params)
        ^^^^^^^^^^^^^^^^^^^^^^^^^^^^^^
  File "/Users/evangoulden/.local/share/virtualenvs/nornir_netauto-sh27gIds/lib/python3.11/site-packages/nornir_napalm/plugins/tasks/napalm_get.py", line 32, in napalm_get
    device = task.host.get_connection(CONNECTION_NAME, task.nornir.config)
             ^^^^^^^^^^^^^^^^^^^^^^^^^^^^^^^^^^^^^^^^^^^^^^^^^^^^^^^^^^^^^
  File "/Users/evangoulden/.local/share/virtualenvs/nornir_netauto-sh27gIds/lib/python3.11/site-packages/nornir/core/inventory.py", line 476, in get_connection
    self.open_connection(
  File "/Users/evangoulden/.local/share/virtualenvs/nornir_netauto-sh27gIds/lib/python3.11/site-packages/nornir/core/inventory.py", line 528, in open_connection
    conn_obj.open(
  File "/Users/evangoulden/.local/share/virtualenvs/nornir_netauto-sh27gIds/lib/python3.11/site-packages/nornir_napalm/plugins/connections/__init__.py", line 57, in open
    connection.open()
  File "/Users/evangoulden/.local/share/virtualenvs/nornir_netauto-sh27gIds/lib/python3.11/site-packages/napalm/ios/ios.py", line 173, in open
    self.device = self._netmiko_open(
                  ^^^^^^^^^^^^^^^^^^^
  File "/Users/evangoulden/.local/share/virtualenvs/nornir_netauto-sh27gIds/lib/python3.11/site-packages/napalm/base/base.py", line 123, in _netmiko_open
    raise ConnectionException("Cannot connect to {}".format(self.hostname))
napalm.base.exceptions.ConnectionException: Cannot connect to 10.139.2.19

2025-03-18 10:09:41,355 - nornir.core.task -    ERROR -      start() - Host 'fg-core-3850': task 'backup_config' failed with traceback:
Traceback (most recent call last):
  File "/Users/evangoulden/.local/share/virtualenvs/nornir_netauto-sh27gIds/lib/python3.11/site-packages/nornir/core/task.py", line 98, in start
    r = self.task(self, **self.params)
        ^^^^^^^^^^^^^^^^^^^^^^^^^^^^^^
  File "/Users/evangoulden/Code/nornir_netauto/netauto.py", line 36, in backup_config
    result = task.run(task=napalm_get, getters=["config"])
             ^^^^^^^^^^^^^^^^^^^^^^^^^^^^^^^^^^^^^^^^^^^^^
  File "/Users/evangoulden/.local/share/virtualenvs/nornir_netauto-sh27gIds/lib/python3.11/site-packages/nornir/core/task.py", line 173, in run
    raise NornirSubTaskError(task=run_task, result=r)
nornir.core.exceptions.NornirSubTaskError: Subtask: napalm_get (failed)


2025-03-18 10:09:41,356 - nornir.core.task -    ERROR -      start() - Host 'buildroom': task 'backup_config' failed with traceback:
Traceback (most recent call last):
  File "/Users/evangoulden/.local/share/virtualenvs/nornir_netauto-sh27gIds/lib/python3.11/site-packages/nornir/core/task.py", line 98, in start
    r = self.task(self, **self.params)
        ^^^^^^^^^^^^^^^^^^^^^^^^^^^^^^
  File "/Users/evangoulden/Code/nornir_netauto/netauto.py", line 36, in backup_config
    result = task.run(task=napalm_get, getters=["config"])
             ^^^^^^^^^^^^^^^^^^^^^^^^^^^^^^^^^^^^^^^^^^^^^
  File "/Users/evangoulden/.local/share/virtualenvs/nornir_netauto-sh27gIds/lib/python3.11/site-packages/nornir/core/task.py", line 173, in run
    raise NornirSubTaskError(task=run_task, result=r)
nornir.core.exceptions.NornirSubTaskError: Subtask: napalm_get (failed)


2025-03-18 10:10:01,338 - nornir.core.task -    ERROR -      start() - Host 'SF-CORE-DMZ-SRX345-0': task 'napalm_get' failed with traceback:
Traceback (most recent call last):
  File "/Users/evangoulden/.local/share/virtualenvs/nornir_netauto-sh27gIds/lib/python3.11/site-packages/jnpr/junos/device.py", line 1390, in open
    self._conn = netconf_ssh.connect(
                 ^^^^^^^^^^^^^^^^^^^^
  File "/Users/evangoulden/.local/share/virtualenvs/nornir_netauto-sh27gIds/lib/python3.11/site-packages/ncclient/manager.py", line 187, in connect
    return connect_ssh(*args, **kwds)
           ^^^^^^^^^^^^^^^^^^^^^^^^^^
  File "/Users/evangoulden/.local/share/virtualenvs/nornir_netauto-sh27gIds/lib/python3.11/site-packages/ncclient/manager.py", line 139, in connect_ssh
    session.connect(*args, **kwds)
  File "/Users/evangoulden/.local/share/virtualenvs/nornir_netauto-sh27gIds/lib/python3.11/site-packages/ncclient/transport/ssh.py", line 288, in connect
    raise SSHError("Could not open socket to %s:%s" % (host, port))
ncclient.transport.errors.SSHError: Could not open socket to 10.139.2.62:22

During handling of the above exception, another exception occurred:

Traceback (most recent call last):
  File "/Users/evangoulden/.local/share/virtualenvs/nornir_netauto-sh27gIds/lib/python3.11/site-packages/napalm/junos/junos.py", line 143, in open
    self.device.open(auto_probe=self.auto_probe)
  File "/Users/evangoulden/.local/share/virtualenvs/nornir_netauto-sh27gIds/lib/python3.11/site-packages/jnpr/junos/device.py", line 1431, in open
    raise EzErrors.ConnectTimeoutError(self)
jnpr.junos.exception.ConnectTimeoutError: ConnectTimeoutError(10.139.2.62)

The above exception was the direct cause of the following exception:

Traceback (most recent call last):
  File "/Users/evangoulden/.local/share/virtualenvs/nornir_netauto-sh27gIds/lib/python3.11/site-packages/nornir/core/task.py", line 98, in start
    r = self.task(self, **self.params)
        ^^^^^^^^^^^^^^^^^^^^^^^^^^^^^^
  File "/Users/evangoulden/.local/share/virtualenvs/nornir_netauto-sh27gIds/lib/python3.11/site-packages/nornir_napalm/plugins/tasks/napalm_get.py", line 32, in napalm_get
    device = task.host.get_connection(CONNECTION_NAME, task.nornir.config)
             ^^^^^^^^^^^^^^^^^^^^^^^^^^^^^^^^^^^^^^^^^^^^^^^^^^^^^^^^^^^^^
  File "/Users/evangoulden/.local/share/virtualenvs/nornir_netauto-sh27gIds/lib/python3.11/site-packages/nornir/core/inventory.py", line 476, in get_connection
    self.open_connection(
  File "/Users/evangoulden/.local/share/virtualenvs/nornir_netauto-sh27gIds/lib/python3.11/site-packages/nornir/core/inventory.py", line 528, in open_connection
    conn_obj.open(
  File "/Users/evangoulden/.local/share/virtualenvs/nornir_netauto-sh27gIds/lib/python3.11/site-packages/nornir_napalm/plugins/connections/__init__.py", line 57, in open
    connection.open()
  File "/Users/evangoulden/.local/share/virtualenvs/nornir_netauto-sh27gIds/lib/python3.11/site-packages/napalm/junos/junos.py", line 145, in open
    raise ConnectionException(cte.msg) from cte
napalm.base.exceptions.ConnectionException: None

2025-03-18 10:10:01,339 - nornir.core.task -    ERROR -      start() - Host 'SF-CORE-DMZ-SRX345-0': task 'backup_config' failed with traceback:
Traceback (most recent call last):
  File "/Users/evangoulden/.local/share/virtualenvs/nornir_netauto-sh27gIds/lib/python3.11/site-packages/nornir/core/task.py", line 98, in start
    r = self.task(self, **self.params)
        ^^^^^^^^^^^^^^^^^^^^^^^^^^^^^^
  File "/Users/evangoulden/Code/nornir_netauto/netauto.py", line 36, in backup_config
    result = task.run(task=napalm_get, getters=["config"])
             ^^^^^^^^^^^^^^^^^^^^^^^^^^^^^^^^^^^^^^^^^^^^^
  File "/Users/evangoulden/.local/share/virtualenvs/nornir_netauto-sh27gIds/lib/python3.11/site-packages/nornir/core/task.py", line 173, in run
    raise NornirSubTaskError(task=run_task, result=r)
nornir.core.exceptions.NornirSubTaskError: Subtask: napalm_get (failed)


2025-03-18 10:12:32,728 -  nornir.core -     INFO -        run() - Running task 'backup_config' with args {} on 3 hosts
2025-03-18 10:12:42,751 - nornir.core.task -    ERROR -      start() - Host 'fg-core-3850': task 'napalm_get' failed with traceback:
Traceback (most recent call last):
  File "/Users/evangoulden/.local/share/virtualenvs/nornir_netauto-sh27gIds/lib/python3.11/site-packages/netmiko/base_connection.py", line 1142, in establish_connection
    self.remote_conn_pre.connect(**ssh_connect_params)
  File "/Users/evangoulden/.local/share/virtualenvs/nornir_netauto-sh27gIds/lib/python3.11/site-packages/paramiko/client.py", line 386, in connect
    sock.connect(addr)
TimeoutError: timed out

During handling of the above exception, another exception occurred:

Traceback (most recent call last):
  File "/Users/evangoulden/.local/share/virtualenvs/nornir_netauto-sh27gIds/lib/python3.11/site-packages/napalm/base/base.py", line 114, in _netmiko_open
    self._netmiko_device = ConnectHandler(
                           ^^^^^^^^^^^^^^^
  File "/Users/evangoulden/.local/share/virtualenvs/nornir_netauto-sh27gIds/lib/python3.11/site-packages/netmiko/ssh_dispatcher.py", line 410, in ConnectHandler
    return ConnectionClass(*args, **kwargs)
           ^^^^^^^^^^^^^^^^^^^^^^^^^^^^^^^^
  File "/Users/evangoulden/.local/share/virtualenvs/nornir_netauto-sh27gIds/lib/python3.11/site-packages/netmiko/base_connection.py", line 493, in __init__
    self._open()
  File "/Users/evangoulden/.local/share/virtualenvs/nornir_netauto-sh27gIds/lib/python3.11/site-packages/netmiko/base_connection.py", line 498, in _open
    self.establish_connection()
  File "/Users/evangoulden/.local/share/virtualenvs/nornir_netauto-sh27gIds/lib/python3.11/site-packages/netmiko/base_connection.py", line 1164, in establish_connection
    raise NetmikoTimeoutException(msg)
netmiko.exceptions.NetmikoTimeoutException: TCP connection to device failed.

Common causes of this problem are:
1. Incorrect hostname or IP address.
2. Wrong TCP port.
3. Intermediate firewall blocking access.

Device settings: cisco_ios 10.141.14.1:22



During handling of the above exception, another exception occurred:

Traceback (most recent call last):
  File "/Users/evangoulden/.local/share/virtualenvs/nornir_netauto-sh27gIds/lib/python3.11/site-packages/nornir/core/task.py", line 98, in start
    r = self.task(self, **self.params)
        ^^^^^^^^^^^^^^^^^^^^^^^^^^^^^^
  File "/Users/evangoulden/.local/share/virtualenvs/nornir_netauto-sh27gIds/lib/python3.11/site-packages/nornir_napalm/plugins/tasks/napalm_get.py", line 32, in napalm_get
    device = task.host.get_connection(CONNECTION_NAME, task.nornir.config)
             ^^^^^^^^^^^^^^^^^^^^^^^^^^^^^^^^^^^^^^^^^^^^^^^^^^^^^^^^^^^^^
  File "/Users/evangoulden/.local/share/virtualenvs/nornir_netauto-sh27gIds/lib/python3.11/site-packages/nornir/core/inventory.py", line 476, in get_connection
    self.open_connection(
  File "/Users/evangoulden/.local/share/virtualenvs/nornir_netauto-sh27gIds/lib/python3.11/site-packages/nornir/core/inventory.py", line 528, in open_connection
    conn_obj.open(
  File "/Users/evangoulden/.local/share/virtualenvs/nornir_netauto-sh27gIds/lib/python3.11/site-packages/nornir_napalm/plugins/connections/__init__.py", line 57, in open
    connection.open()
  File "/Users/evangoulden/.local/share/virtualenvs/nornir_netauto-sh27gIds/lib/python3.11/site-packages/napalm/ios/ios.py", line 173, in open
    self.device = self._netmiko_open(
                  ^^^^^^^^^^^^^^^^^^^
  File "/Users/evangoulden/.local/share/virtualenvs/nornir_netauto-sh27gIds/lib/python3.11/site-packages/napalm/base/base.py", line 123, in _netmiko_open
    raise ConnectionException("Cannot connect to {}".format(self.hostname))
napalm.base.exceptions.ConnectionException: Cannot connect to 10.141.14.1

2025-03-18 10:12:42,751 - nornir.core.task -    ERROR -      start() - Host 'buildroom': task 'napalm_get' failed with traceback:
Traceback (most recent call last):
  File "/Users/evangoulden/.local/share/virtualenvs/nornir_netauto-sh27gIds/lib/python3.11/site-packages/netmiko/base_connection.py", line 1142, in establish_connection
    self.remote_conn_pre.connect(**ssh_connect_params)
  File "/Users/evangoulden/.local/share/virtualenvs/nornir_netauto-sh27gIds/lib/python3.11/site-packages/paramiko/client.py", line 386, in connect
    sock.connect(addr)
TimeoutError: timed out

During handling of the above exception, another exception occurred:

Traceback (most recent call last):
  File "/Users/evangoulden/.local/share/virtualenvs/nornir_netauto-sh27gIds/lib/python3.11/site-packages/napalm/base/base.py", line 114, in _netmiko_open
    self._netmiko_device = ConnectHandler(
                           ^^^^^^^^^^^^^^^
  File "/Users/evangoulden/.local/share/virtualenvs/nornir_netauto-sh27gIds/lib/python3.11/site-packages/netmiko/ssh_dispatcher.py", line 410, in ConnectHandler
    return ConnectionClass(*args, **kwargs)
           ^^^^^^^^^^^^^^^^^^^^^^^^^^^^^^^^
  File "/Users/evangoulden/.local/share/virtualenvs/nornir_netauto-sh27gIds/lib/python3.11/site-packages/netmiko/base_connection.py", line 493, in __init__
    self._open()
  File "/Users/evangoulden/.local/share/virtualenvs/nornir_netauto-sh27gIds/lib/python3.11/site-packages/netmiko/base_connection.py", line 498, in _open
    self.establish_connection()
  File "/Users/evangoulden/.local/share/virtualenvs/nornir_netauto-sh27gIds/lib/python3.11/site-packages/netmiko/base_connection.py", line 1164, in establish_connection
    raise NetmikoTimeoutException(msg)
netmiko.exceptions.NetmikoTimeoutException: TCP connection to device failed.

Common causes of this problem are:
1. Incorrect hostname or IP address.
2. Wrong TCP port.
3. Intermediate firewall blocking access.

Device settings: cisco_ios 10.139.2.19:22



During handling of the above exception, another exception occurred:

Traceback (most recent call last):
  File "/Users/evangoulden/.local/share/virtualenvs/nornir_netauto-sh27gIds/lib/python3.11/site-packages/nornir/core/task.py", line 98, in start
    r = self.task(self, **self.params)
        ^^^^^^^^^^^^^^^^^^^^^^^^^^^^^^
  File "/Users/evangoulden/.local/share/virtualenvs/nornir_netauto-sh27gIds/lib/python3.11/site-packages/nornir_napalm/plugins/tasks/napalm_get.py", line 32, in napalm_get
    device = task.host.get_connection(CONNECTION_NAME, task.nornir.config)
             ^^^^^^^^^^^^^^^^^^^^^^^^^^^^^^^^^^^^^^^^^^^^^^^^^^^^^^^^^^^^^
  File "/Users/evangoulden/.local/share/virtualenvs/nornir_netauto-sh27gIds/lib/python3.11/site-packages/nornir/core/inventory.py", line 476, in get_connection
    self.open_connection(
  File "/Users/evangoulden/.local/share/virtualenvs/nornir_netauto-sh27gIds/lib/python3.11/site-packages/nornir/core/inventory.py", line 528, in open_connection
    conn_obj.open(
  File "/Users/evangoulden/.local/share/virtualenvs/nornir_netauto-sh27gIds/lib/python3.11/site-packages/nornir_napalm/plugins/connections/__init__.py", line 57, in open
    connection.open()
  File "/Users/evangoulden/.local/share/virtualenvs/nornir_netauto-sh27gIds/lib/python3.11/site-packages/napalm/ios/ios.py", line 173, in open
    self.device = self._netmiko_open(
                  ^^^^^^^^^^^^^^^^^^^
  File "/Users/evangoulden/.local/share/virtualenvs/nornir_netauto-sh27gIds/lib/python3.11/site-packages/napalm/base/base.py", line 123, in _netmiko_open
    raise ConnectionException("Cannot connect to {}".format(self.hostname))
napalm.base.exceptions.ConnectionException: Cannot connect to 10.139.2.19

2025-03-18 10:12:42,752 - nornir.core.task -    ERROR -      start() - Host 'fg-core-3850': task 'backup_config' failed with traceback:
Traceback (most recent call last):
  File "/Users/evangoulden/.local/share/virtualenvs/nornir_netauto-sh27gIds/lib/python3.11/site-packages/nornir/core/task.py", line 98, in start
    r = self.task(self, **self.params)
        ^^^^^^^^^^^^^^^^^^^^^^^^^^^^^^
  File "/Users/evangoulden/Code/nornir_netauto/netauto.py", line 36, in backup_config
    result = task.run(task=napalm_get, getters=["config"])
             ^^^^^^^^^^^^^^^^^^^^^^^^^^^^^^^^^^^^^^^^^^^^^
  File "/Users/evangoulden/.local/share/virtualenvs/nornir_netauto-sh27gIds/lib/python3.11/site-packages/nornir/core/task.py", line 173, in run
    raise NornirSubTaskError(task=run_task, result=r)
nornir.core.exceptions.NornirSubTaskError: Subtask: napalm_get (failed)


2025-03-18 10:12:42,753 - nornir.core.task -    ERROR -      start() - Host 'buildroom': task 'backup_config' failed with traceback:
Traceback (most recent call last):
  File "/Users/evangoulden/.local/share/virtualenvs/nornir_netauto-sh27gIds/lib/python3.11/site-packages/nornir/core/task.py", line 98, in start
    r = self.task(self, **self.params)
        ^^^^^^^^^^^^^^^^^^^^^^^^^^^^^^
  File "/Users/evangoulden/Code/nornir_netauto/netauto.py", line 36, in backup_config
    result = task.run(task=napalm_get, getters=["config"])
             ^^^^^^^^^^^^^^^^^^^^^^^^^^^^^^^^^^^^^^^^^^^^^
  File "/Users/evangoulden/.local/share/virtualenvs/nornir_netauto-sh27gIds/lib/python3.11/site-packages/nornir/core/task.py", line 173, in run
    raise NornirSubTaskError(task=run_task, result=r)
nornir.core.exceptions.NornirSubTaskError: Subtask: napalm_get (failed)


2025-03-18 10:13:02,736 - nornir.core.task -    ERROR -      start() - Host 'SF-CORE-DMZ-SRX345-0': task 'napalm_get' failed with traceback:
Traceback (most recent call last):
  File "/Users/evangoulden/.local/share/virtualenvs/nornir_netauto-sh27gIds/lib/python3.11/site-packages/jnpr/junos/device.py", line 1390, in open
    self._conn = netconf_ssh.connect(
                 ^^^^^^^^^^^^^^^^^^^^
  File "/Users/evangoulden/.local/share/virtualenvs/nornir_netauto-sh27gIds/lib/python3.11/site-packages/ncclient/manager.py", line 187, in connect
    return connect_ssh(*args, **kwds)
           ^^^^^^^^^^^^^^^^^^^^^^^^^^
  File "/Users/evangoulden/.local/share/virtualenvs/nornir_netauto-sh27gIds/lib/python3.11/site-packages/ncclient/manager.py", line 139, in connect_ssh
    session.connect(*args, **kwds)
  File "/Users/evangoulden/.local/share/virtualenvs/nornir_netauto-sh27gIds/lib/python3.11/site-packages/ncclient/transport/ssh.py", line 288, in connect
    raise SSHError("Could not open socket to %s:%s" % (host, port))
ncclient.transport.errors.SSHError: Could not open socket to 10.139.2.62:22

During handling of the above exception, another exception occurred:

Traceback (most recent call last):
  File "/Users/evangoulden/.local/share/virtualenvs/nornir_netauto-sh27gIds/lib/python3.11/site-packages/napalm/junos/junos.py", line 143, in open
    self.device.open(auto_probe=self.auto_probe)
  File "/Users/evangoulden/.local/share/virtualenvs/nornir_netauto-sh27gIds/lib/python3.11/site-packages/jnpr/junos/device.py", line 1431, in open
    raise EzErrors.ConnectTimeoutError(self)
jnpr.junos.exception.ConnectTimeoutError: ConnectTimeoutError(10.139.2.62)

The above exception was the direct cause of the following exception:

Traceback (most recent call last):
  File "/Users/evangoulden/.local/share/virtualenvs/nornir_netauto-sh27gIds/lib/python3.11/site-packages/nornir/core/task.py", line 98, in start
    r = self.task(self, **self.params)
        ^^^^^^^^^^^^^^^^^^^^^^^^^^^^^^
  File "/Users/evangoulden/.local/share/virtualenvs/nornir_netauto-sh27gIds/lib/python3.11/site-packages/nornir_napalm/plugins/tasks/napalm_get.py", line 32, in napalm_get
    device = task.host.get_connection(CONNECTION_NAME, task.nornir.config)
             ^^^^^^^^^^^^^^^^^^^^^^^^^^^^^^^^^^^^^^^^^^^^^^^^^^^^^^^^^^^^^
  File "/Users/evangoulden/.local/share/virtualenvs/nornir_netauto-sh27gIds/lib/python3.11/site-packages/nornir/core/inventory.py", line 476, in get_connection
    self.open_connection(
  File "/Users/evangoulden/.local/share/virtualenvs/nornir_netauto-sh27gIds/lib/python3.11/site-packages/nornir/core/inventory.py", line 528, in open_connection
    conn_obj.open(
  File "/Users/evangoulden/.local/share/virtualenvs/nornir_netauto-sh27gIds/lib/python3.11/site-packages/nornir_napalm/plugins/connections/__init__.py", line 57, in open
    connection.open()
  File "/Users/evangoulden/.local/share/virtualenvs/nornir_netauto-sh27gIds/lib/python3.11/site-packages/napalm/junos/junos.py", line 145, in open
    raise ConnectionException(cte.msg) from cte
napalm.base.exceptions.ConnectionException: None

2025-03-18 10:13:02,737 - nornir.core.task -    ERROR -      start() - Host 'SF-CORE-DMZ-SRX345-0': task 'backup_config' failed with traceback:
Traceback (most recent call last):
  File "/Users/evangoulden/.local/share/virtualenvs/nornir_netauto-sh27gIds/lib/python3.11/site-packages/nornir/core/task.py", line 98, in start
    r = self.task(self, **self.params)
        ^^^^^^^^^^^^^^^^^^^^^^^^^^^^^^
  File "/Users/evangoulden/Code/nornir_netauto/netauto.py", line 36, in backup_config
    result = task.run(task=napalm_get, getters=["config"])
             ^^^^^^^^^^^^^^^^^^^^^^^^^^^^^^^^^^^^^^^^^^^^^
  File "/Users/evangoulden/.local/share/virtualenvs/nornir_netauto-sh27gIds/lib/python3.11/site-packages/nornir/core/task.py", line 173, in run
    raise NornirSubTaskError(task=run_task, result=r)
nornir.core.exceptions.NornirSubTaskError: Subtask: napalm_get (failed)


2025-03-18 10:28:15,701 -  nornir.core -     INFO -        run() - Running task 'backup_config' with args {} on 3 hosts
2025-03-18 10:28:25,707 - nornir.core.task -    ERROR -      start() - Host 'fg-core-3850': task 'napalm_get' failed with traceback:
Traceback (most recent call last):
  File "/Users/evangoulden/.local/share/virtualenvs/nornir_netauto-sh27gIds/lib/python3.11/site-packages/netmiko/base_connection.py", line 1142, in establish_connection
    self.remote_conn_pre.connect(**ssh_connect_params)
  File "/Users/evangoulden/.local/share/virtualenvs/nornir_netauto-sh27gIds/lib/python3.11/site-packages/paramiko/client.py", line 386, in connect
    sock.connect(addr)
TimeoutError: timed out

During handling of the above exception, another exception occurred:

Traceback (most recent call last):
  File "/Users/evangoulden/.local/share/virtualenvs/nornir_netauto-sh27gIds/lib/python3.11/site-packages/napalm/base/base.py", line 114, in _netmiko_open
    self._netmiko_device = ConnectHandler(
                           ^^^^^^^^^^^^^^^
  File "/Users/evangoulden/.local/share/virtualenvs/nornir_netauto-sh27gIds/lib/python3.11/site-packages/netmiko/ssh_dispatcher.py", line 410, in ConnectHandler
    return ConnectionClass(*args, **kwargs)
           ^^^^^^^^^^^^^^^^^^^^^^^^^^^^^^^^
  File "/Users/evangoulden/.local/share/virtualenvs/nornir_netauto-sh27gIds/lib/python3.11/site-packages/netmiko/base_connection.py", line 493, in __init__
    self._open()
  File "/Users/evangoulden/.local/share/virtualenvs/nornir_netauto-sh27gIds/lib/python3.11/site-packages/netmiko/base_connection.py", line 498, in _open
    self.establish_connection()
  File "/Users/evangoulden/.local/share/virtualenvs/nornir_netauto-sh27gIds/lib/python3.11/site-packages/netmiko/base_connection.py", line 1164, in establish_connection
    raise NetmikoTimeoutException(msg)
netmiko.exceptions.NetmikoTimeoutException: TCP connection to device failed.

Common causes of this problem are:
1. Incorrect hostname or IP address.
2. Wrong TCP port.
3. Intermediate firewall blocking access.

Device settings: cisco_ios 10.141.14.1:22



During handling of the above exception, another exception occurred:

Traceback (most recent call last):
  File "/Users/evangoulden/.local/share/virtualenvs/nornir_netauto-sh27gIds/lib/python3.11/site-packages/nornir/core/task.py", line 98, in start
    r = self.task(self, **self.params)
        ^^^^^^^^^^^^^^^^^^^^^^^^^^^^^^
  File "/Users/evangoulden/.local/share/virtualenvs/nornir_netauto-sh27gIds/lib/python3.11/site-packages/nornir_napalm/plugins/tasks/napalm_get.py", line 32, in napalm_get
    device = task.host.get_connection(CONNECTION_NAME, task.nornir.config)
             ^^^^^^^^^^^^^^^^^^^^^^^^^^^^^^^^^^^^^^^^^^^^^^^^^^^^^^^^^^^^^
  File "/Users/evangoulden/.local/share/virtualenvs/nornir_netauto-sh27gIds/lib/python3.11/site-packages/nornir/core/inventory.py", line 476, in get_connection
    self.open_connection(
  File "/Users/evangoulden/.local/share/virtualenvs/nornir_netauto-sh27gIds/lib/python3.11/site-packages/nornir/core/inventory.py", line 528, in open_connection
    conn_obj.open(
  File "/Users/evangoulden/.local/share/virtualenvs/nornir_netauto-sh27gIds/lib/python3.11/site-packages/nornir_napalm/plugins/connections/__init__.py", line 57, in open
    connection.open()
  File "/Users/evangoulden/.local/share/virtualenvs/nornir_netauto-sh27gIds/lib/python3.11/site-packages/napalm/ios/ios.py", line 173, in open
    self.device = self._netmiko_open(
                  ^^^^^^^^^^^^^^^^^^^
  File "/Users/evangoulden/.local/share/virtualenvs/nornir_netauto-sh27gIds/lib/python3.11/site-packages/napalm/base/base.py", line 123, in _netmiko_open
    raise ConnectionException("Cannot connect to {}".format(self.hostname))
napalm.base.exceptions.ConnectionException: Cannot connect to 10.141.14.1

2025-03-18 10:28:25,707 - nornir.core.task -    ERROR -      start() - Host 'buildroom': task 'napalm_get' failed with traceback:
Traceback (most recent call last):
  File "/Users/evangoulden/.local/share/virtualenvs/nornir_netauto-sh27gIds/lib/python3.11/site-packages/netmiko/base_connection.py", line 1142, in establish_connection
    self.remote_conn_pre.connect(**ssh_connect_params)
  File "/Users/evangoulden/.local/share/virtualenvs/nornir_netauto-sh27gIds/lib/python3.11/site-packages/paramiko/client.py", line 386, in connect
    sock.connect(addr)
TimeoutError: timed out

During handling of the above exception, another exception occurred:

Traceback (most recent call last):
  File "/Users/evangoulden/.local/share/virtualenvs/nornir_netauto-sh27gIds/lib/python3.11/site-packages/napalm/base/base.py", line 114, in _netmiko_open
    self._netmiko_device = ConnectHandler(
                           ^^^^^^^^^^^^^^^
  File "/Users/evangoulden/.local/share/virtualenvs/nornir_netauto-sh27gIds/lib/python3.11/site-packages/netmiko/ssh_dispatcher.py", line 410, in ConnectHandler
    return ConnectionClass(*args, **kwargs)
           ^^^^^^^^^^^^^^^^^^^^^^^^^^^^^^^^
  File "/Users/evangoulden/.local/share/virtualenvs/nornir_netauto-sh27gIds/lib/python3.11/site-packages/netmiko/base_connection.py", line 493, in __init__
    self._open()
  File "/Users/evangoulden/.local/share/virtualenvs/nornir_netauto-sh27gIds/lib/python3.11/site-packages/netmiko/base_connection.py", line 498, in _open
    self.establish_connection()
  File "/Users/evangoulden/.local/share/virtualenvs/nornir_netauto-sh27gIds/lib/python3.11/site-packages/netmiko/base_connection.py", line 1164, in establish_connection
    raise NetmikoTimeoutException(msg)
netmiko.exceptions.NetmikoTimeoutException: TCP connection to device failed.

Common causes of this problem are:
1. Incorrect hostname or IP address.
2. Wrong TCP port.
3. Intermediate firewall blocking access.

Device settings: cisco_ios 10.139.2.19:22



During handling of the above exception, another exception occurred:

Traceback (most recent call last):
  File "/Users/evangoulden/.local/share/virtualenvs/nornir_netauto-sh27gIds/lib/python3.11/site-packages/nornir/core/task.py", line 98, in start
    r = self.task(self, **self.params)
        ^^^^^^^^^^^^^^^^^^^^^^^^^^^^^^
  File "/Users/evangoulden/.local/share/virtualenvs/nornir_netauto-sh27gIds/lib/python3.11/site-packages/nornir_napalm/plugins/tasks/napalm_get.py", line 32, in napalm_get
    device = task.host.get_connection(CONNECTION_NAME, task.nornir.config)
             ^^^^^^^^^^^^^^^^^^^^^^^^^^^^^^^^^^^^^^^^^^^^^^^^^^^^^^^^^^^^^
  File "/Users/evangoulden/.local/share/virtualenvs/nornir_netauto-sh27gIds/lib/python3.11/site-packages/nornir/core/inventory.py", line 476, in get_connection
    self.open_connection(
  File "/Users/evangoulden/.local/share/virtualenvs/nornir_netauto-sh27gIds/lib/python3.11/site-packages/nornir/core/inventory.py", line 528, in open_connection
    conn_obj.open(
  File "/Users/evangoulden/.local/share/virtualenvs/nornir_netauto-sh27gIds/lib/python3.11/site-packages/nornir_napalm/plugins/connections/__init__.py", line 57, in open
    connection.open()
  File "/Users/evangoulden/.local/share/virtualenvs/nornir_netauto-sh27gIds/lib/python3.11/site-packages/napalm/ios/ios.py", line 173, in open
    self.device = self._netmiko_open(
                  ^^^^^^^^^^^^^^^^^^^
  File "/Users/evangoulden/.local/share/virtualenvs/nornir_netauto-sh27gIds/lib/python3.11/site-packages/napalm/base/base.py", line 123, in _netmiko_open
    raise ConnectionException("Cannot connect to {}".format(self.hostname))
napalm.base.exceptions.ConnectionException: Cannot connect to 10.139.2.19

2025-03-18 10:28:25,707 - nornir.core.task -    ERROR -      start() - Host 'fg-core-3850': task 'backup_config' failed with traceback:
Traceback (most recent call last):
  File "/Users/evangoulden/.local/share/virtualenvs/nornir_netauto-sh27gIds/lib/python3.11/site-packages/nornir/core/task.py", line 98, in start
    r = self.task(self, **self.params)
        ^^^^^^^^^^^^^^^^^^^^^^^^^^^^^^
  File "/Users/evangoulden/Code/nornir_netauto/netauto.py", line 35, in backup_config
    result = task.run(task=napalm_get, getters=["config"])
             ^^^^^^^^^^^^^^^^^^^^^^^^^^^^^^^^^^^^^^^^^^^^^
  File "/Users/evangoulden/.local/share/virtualenvs/nornir_netauto-sh27gIds/lib/python3.11/site-packages/nornir/core/task.py", line 173, in run
    raise NornirSubTaskError(task=run_task, result=r)
nornir.core.exceptions.NornirSubTaskError: Subtask: napalm_get (failed)


2025-03-18 10:28:25,708 - nornir.core.task -    ERROR -      start() - Host 'buildroom': task 'backup_config' failed with traceback:
Traceback (most recent call last):
  File "/Users/evangoulden/.local/share/virtualenvs/nornir_netauto-sh27gIds/lib/python3.11/site-packages/nornir/core/task.py", line 98, in start
    r = self.task(self, **self.params)
        ^^^^^^^^^^^^^^^^^^^^^^^^^^^^^^
  File "/Users/evangoulden/Code/nornir_netauto/netauto.py", line 35, in backup_config
    result = task.run(task=napalm_get, getters=["config"])
             ^^^^^^^^^^^^^^^^^^^^^^^^^^^^^^^^^^^^^^^^^^^^^
  File "/Users/evangoulden/.local/share/virtualenvs/nornir_netauto-sh27gIds/lib/python3.11/site-packages/nornir/core/task.py", line 173, in run
    raise NornirSubTaskError(task=run_task, result=r)
nornir.core.exceptions.NornirSubTaskError: Subtask: napalm_get (failed)


2025-03-18 10:28:45,711 - nornir.core.task -    ERROR -      start() - Host 'SF-CORE-DMZ-SRX345-0': task 'napalm_get' failed with traceback:
Traceback (most recent call last):
  File "/Users/evangoulden/.local/share/virtualenvs/nornir_netauto-sh27gIds/lib/python3.11/site-packages/jnpr/junos/device.py", line 1390, in open
    self._conn = netconf_ssh.connect(
                 ^^^^^^^^^^^^^^^^^^^^
  File "/Users/evangoulden/.local/share/virtualenvs/nornir_netauto-sh27gIds/lib/python3.11/site-packages/ncclient/manager.py", line 187, in connect
    return connect_ssh(*args, **kwds)
           ^^^^^^^^^^^^^^^^^^^^^^^^^^
  File "/Users/evangoulden/.local/share/virtualenvs/nornir_netauto-sh27gIds/lib/python3.11/site-packages/ncclient/manager.py", line 139, in connect_ssh
    session.connect(*args, **kwds)
  File "/Users/evangoulden/.local/share/virtualenvs/nornir_netauto-sh27gIds/lib/python3.11/site-packages/ncclient/transport/ssh.py", line 288, in connect
    raise SSHError("Could not open socket to %s:%s" % (host, port))
ncclient.transport.errors.SSHError: Could not open socket to 10.139.2.62:22

During handling of the above exception, another exception occurred:

Traceback (most recent call last):
  File "/Users/evangoulden/.local/share/virtualenvs/nornir_netauto-sh27gIds/lib/python3.11/site-packages/napalm/junos/junos.py", line 143, in open
    self.device.open(auto_probe=self.auto_probe)
  File "/Users/evangoulden/.local/share/virtualenvs/nornir_netauto-sh27gIds/lib/python3.11/site-packages/jnpr/junos/device.py", line 1431, in open
    raise EzErrors.ConnectTimeoutError(self)
jnpr.junos.exception.ConnectTimeoutError: ConnectTimeoutError(10.139.2.62)

The above exception was the direct cause of the following exception:

Traceback (most recent call last):
  File "/Users/evangoulden/.local/share/virtualenvs/nornir_netauto-sh27gIds/lib/python3.11/site-packages/nornir/core/task.py", line 98, in start
    r = self.task(self, **self.params)
        ^^^^^^^^^^^^^^^^^^^^^^^^^^^^^^
  File "/Users/evangoulden/.local/share/virtualenvs/nornir_netauto-sh27gIds/lib/python3.11/site-packages/nornir_napalm/plugins/tasks/napalm_get.py", line 32, in napalm_get
    device = task.host.get_connection(CONNECTION_NAME, task.nornir.config)
             ^^^^^^^^^^^^^^^^^^^^^^^^^^^^^^^^^^^^^^^^^^^^^^^^^^^^^^^^^^^^^
  File "/Users/evangoulden/.local/share/virtualenvs/nornir_netauto-sh27gIds/lib/python3.11/site-packages/nornir/core/inventory.py", line 476, in get_connection
    self.open_connection(
  File "/Users/evangoulden/.local/share/virtualenvs/nornir_netauto-sh27gIds/lib/python3.11/site-packages/nornir/core/inventory.py", line 528, in open_connection
    conn_obj.open(
  File "/Users/evangoulden/.local/share/virtualenvs/nornir_netauto-sh27gIds/lib/python3.11/site-packages/nornir_napalm/plugins/connections/__init__.py", line 57, in open
    connection.open()
  File "/Users/evangoulden/.local/share/virtualenvs/nornir_netauto-sh27gIds/lib/python3.11/site-packages/napalm/junos/junos.py", line 145, in open
    raise ConnectionException(cte.msg) from cte
napalm.base.exceptions.ConnectionException: None

2025-03-18 10:28:45,712 - nornir.core.task -    ERROR -      start() - Host 'SF-CORE-DMZ-SRX345-0': task 'backup_config' failed with traceback:
Traceback (most recent call last):
  File "/Users/evangoulden/.local/share/virtualenvs/nornir_netauto-sh27gIds/lib/python3.11/site-packages/nornir/core/task.py", line 98, in start
    r = self.task(self, **self.params)
        ^^^^^^^^^^^^^^^^^^^^^^^^^^^^^^
  File "/Users/evangoulden/Code/nornir_netauto/netauto.py", line 35, in backup_config
    result = task.run(task=napalm_get, getters=["config"])
             ^^^^^^^^^^^^^^^^^^^^^^^^^^^^^^^^^^^^^^^^^^^^^
  File "/Users/evangoulden/.local/share/virtualenvs/nornir_netauto-sh27gIds/lib/python3.11/site-packages/nornir/core/task.py", line 173, in run
    raise NornirSubTaskError(task=run_task, result=r)
nornir.core.exceptions.NornirSubTaskError: Subtask: napalm_get (failed)


2025-03-18 10:29:15,021 -  nornir.core -     INFO -        run() - Running task 'backup_config' with args {} on 3 hosts
2025-03-18 10:29:15,089 - nornir.core.task -    ERROR -      start() - Host 'fg-core-3850': task 'napalm_get' failed with traceback:
Traceback (most recent call last):
  File "/Users/evangoulden/.local/share/virtualenvs/nornir_netauto-sh27gIds/lib/python3.11/site-packages/netmiko/base_connection.py", line 1142, in establish_connection
    self.remote_conn_pre.connect(**ssh_connect_params)
  File "/Users/evangoulden/.local/share/virtualenvs/nornir_netauto-sh27gIds/lib/python3.11/site-packages/paramiko/client.py", line 409, in connect
    raise NoValidConnectionsError(errors)
paramiko.ssh_exception.NoValidConnectionsError: [Errno None] Unable to connect to port 22 on 10.141.14.1

During handling of the above exception, another exception occurred:

Traceback (most recent call last):
  File "/Users/evangoulden/.local/share/virtualenvs/nornir_netauto-sh27gIds/lib/python3.11/site-packages/napalm/base/base.py", line 114, in _netmiko_open
    self._netmiko_device = ConnectHandler(
                           ^^^^^^^^^^^^^^^
  File "/Users/evangoulden/.local/share/virtualenvs/nornir_netauto-sh27gIds/lib/python3.11/site-packages/netmiko/ssh_dispatcher.py", line 410, in ConnectHandler
    return ConnectionClass(*args, **kwargs)
           ^^^^^^^^^^^^^^^^^^^^^^^^^^^^^^^^
  File "/Users/evangoulden/.local/share/virtualenvs/nornir_netauto-sh27gIds/lib/python3.11/site-packages/netmiko/base_connection.py", line 493, in __init__
    self._open()
  File "/Users/evangoulden/.local/share/virtualenvs/nornir_netauto-sh27gIds/lib/python3.11/site-packages/netmiko/base_connection.py", line 498, in _open
    self.establish_connection()
  File "/Users/evangoulden/.local/share/virtualenvs/nornir_netauto-sh27gIds/lib/python3.11/site-packages/netmiko/base_connection.py", line 1164, in establish_connection
    raise NetmikoTimeoutException(msg)
netmiko.exceptions.NetmikoTimeoutException: TCP connection to device failed.

Common causes of this problem are:
1. Incorrect hostname or IP address.
2. Wrong TCP port.
3. Intermediate firewall blocking access.

Device settings: cisco_ios 10.141.14.1:22



During handling of the above exception, another exception occurred:

Traceback (most recent call last):
  File "/Users/evangoulden/.local/share/virtualenvs/nornir_netauto-sh27gIds/lib/python3.11/site-packages/nornir/core/task.py", line 98, in start
    r = self.task(self, **self.params)
        ^^^^^^^^^^^^^^^^^^^^^^^^^^^^^^
  File "/Users/evangoulden/.local/share/virtualenvs/nornir_netauto-sh27gIds/lib/python3.11/site-packages/nornir_napalm/plugins/tasks/napalm_get.py", line 32, in napalm_get
    device = task.host.get_connection(CONNECTION_NAME, task.nornir.config)
             ^^^^^^^^^^^^^^^^^^^^^^^^^^^^^^^^^^^^^^^^^^^^^^^^^^^^^^^^^^^^^
  File "/Users/evangoulden/.local/share/virtualenvs/nornir_netauto-sh27gIds/lib/python3.11/site-packages/nornir/core/inventory.py", line 476, in get_connection
    self.open_connection(
  File "/Users/evangoulden/.local/share/virtualenvs/nornir_netauto-sh27gIds/lib/python3.11/site-packages/nornir/core/inventory.py", line 528, in open_connection
    conn_obj.open(
  File "/Users/evangoulden/.local/share/virtualenvs/nornir_netauto-sh27gIds/lib/python3.11/site-packages/nornir_napalm/plugins/connections/__init__.py", line 57, in open
    connection.open()
  File "/Users/evangoulden/.local/share/virtualenvs/nornir_netauto-sh27gIds/lib/python3.11/site-packages/napalm/ios/ios.py", line 173, in open
    self.device = self._netmiko_open(
                  ^^^^^^^^^^^^^^^^^^^
  File "/Users/evangoulden/.local/share/virtualenvs/nornir_netauto-sh27gIds/lib/python3.11/site-packages/napalm/base/base.py", line 123, in _netmiko_open
    raise ConnectionException("Cannot connect to {}".format(self.hostname))
napalm.base.exceptions.ConnectionException: Cannot connect to 10.141.14.1

2025-03-18 10:29:15,089 - nornir.core.task -    ERROR -      start() - Host 'fg-core-3850': task 'backup_config' failed with traceback:
Traceback (most recent call last):
  File "/Users/evangoulden/.local/share/virtualenvs/nornir_netauto-sh27gIds/lib/python3.11/site-packages/nornir/core/task.py", line 98, in start
    r = self.task(self, **self.params)
        ^^^^^^^^^^^^^^^^^^^^^^^^^^^^^^
  File "/Users/evangoulden/Code/nornir_netauto/netauto.py", line 35, in backup_config
    result = task.run(task=napalm_get, getters=["config"])
             ^^^^^^^^^^^^^^^^^^^^^^^^^^^^^^^^^^^^^^^^^^^^^
  File "/Users/evangoulden/.local/share/virtualenvs/nornir_netauto-sh27gIds/lib/python3.11/site-packages/nornir/core/task.py", line 173, in run
    raise NornirSubTaskError(task=run_task, result=r)
nornir.core.exceptions.NornirSubTaskError: Subtask: napalm_get (failed)


2025-03-18 10:31:02,804 -  nornir.core -     INFO -        run() - Running task 'backup_config' with args {} on 3 hosts
2025-03-18 10:31:02,849 - nornir.core.task -    ERROR -      start() - Host 'fg-core-3850': task 'napalm_get' failed with traceback:
Traceback (most recent call last):
  File "/Users/evangoulden/.local/share/virtualenvs/nornir_netauto-sh27gIds/lib/python3.11/site-packages/netmiko/base_connection.py", line 1142, in establish_connection
    self.remote_conn_pre.connect(**ssh_connect_params)
  File "/Users/evangoulden/.local/share/virtualenvs/nornir_netauto-sh27gIds/lib/python3.11/site-packages/paramiko/client.py", line 409, in connect
    raise NoValidConnectionsError(errors)
paramiko.ssh_exception.NoValidConnectionsError: [Errno None] Unable to connect to port 22 on 10.141.14.1

During handling of the above exception, another exception occurred:

Traceback (most recent call last):
  File "/Users/evangoulden/.local/share/virtualenvs/nornir_netauto-sh27gIds/lib/python3.11/site-packages/napalm/base/base.py", line 114, in _netmiko_open
    self._netmiko_device = ConnectHandler(
                           ^^^^^^^^^^^^^^^
  File "/Users/evangoulden/.local/share/virtualenvs/nornir_netauto-sh27gIds/lib/python3.11/site-packages/netmiko/ssh_dispatcher.py", line 410, in ConnectHandler
    return ConnectionClass(*args, **kwargs)
           ^^^^^^^^^^^^^^^^^^^^^^^^^^^^^^^^
  File "/Users/evangoulden/.local/share/virtualenvs/nornir_netauto-sh27gIds/lib/python3.11/site-packages/netmiko/base_connection.py", line 493, in __init__
    self._open()
  File "/Users/evangoulden/.local/share/virtualenvs/nornir_netauto-sh27gIds/lib/python3.11/site-packages/netmiko/base_connection.py", line 498, in _open
    self.establish_connection()
  File "/Users/evangoulden/.local/share/virtualenvs/nornir_netauto-sh27gIds/lib/python3.11/site-packages/netmiko/base_connection.py", line 1164, in establish_connection
    raise NetmikoTimeoutException(msg)
netmiko.exceptions.NetmikoTimeoutException: TCP connection to device failed.

Common causes of this problem are:
1. Incorrect hostname or IP address.
2. Wrong TCP port.
3. Intermediate firewall blocking access.

Device settings: cisco_ios 10.141.14.1:22



During handling of the above exception, another exception occurred:

Traceback (most recent call last):
  File "/Users/evangoulden/.local/share/virtualenvs/nornir_netauto-sh27gIds/lib/python3.11/site-packages/nornir/core/task.py", line 98, in start
    r = self.task(self, **self.params)
        ^^^^^^^^^^^^^^^^^^^^^^^^^^^^^^
  File "/Users/evangoulden/.local/share/virtualenvs/nornir_netauto-sh27gIds/lib/python3.11/site-packages/nornir_napalm/plugins/tasks/napalm_get.py", line 32, in napalm_get
    device = task.host.get_connection(CONNECTION_NAME, task.nornir.config)
             ^^^^^^^^^^^^^^^^^^^^^^^^^^^^^^^^^^^^^^^^^^^^^^^^^^^^^^^^^^^^^
  File "/Users/evangoulden/.local/share/virtualenvs/nornir_netauto-sh27gIds/lib/python3.11/site-packages/nornir/core/inventory.py", line 476, in get_connection
    self.open_connection(
  File "/Users/evangoulden/.local/share/virtualenvs/nornir_netauto-sh27gIds/lib/python3.11/site-packages/nornir/core/inventory.py", line 528, in open_connection
    conn_obj.open(
  File "/Users/evangoulden/.local/share/virtualenvs/nornir_netauto-sh27gIds/lib/python3.11/site-packages/nornir_napalm/plugins/connections/__init__.py", line 57, in open
    connection.open()
  File "/Users/evangoulden/.local/share/virtualenvs/nornir_netauto-sh27gIds/lib/python3.11/site-packages/napalm/ios/ios.py", line 173, in open
    self.device = self._netmiko_open(
                  ^^^^^^^^^^^^^^^^^^^
  File "/Users/evangoulden/.local/share/virtualenvs/nornir_netauto-sh27gIds/lib/python3.11/site-packages/napalm/base/base.py", line 123, in _netmiko_open
    raise ConnectionException("Cannot connect to {}".format(self.hostname))
napalm.base.exceptions.ConnectionException: Cannot connect to 10.141.14.1

2025-03-18 10:31:02,850 - nornir.core.task -    ERROR -      start() - Host 'fg-core-3850': task 'backup_config' failed with traceback:
Traceback (most recent call last):
  File "/Users/evangoulden/.local/share/virtualenvs/nornir_netauto-sh27gIds/lib/python3.11/site-packages/nornir/core/task.py", line 98, in start
    r = self.task(self, **self.params)
        ^^^^^^^^^^^^^^^^^^^^^^^^^^^^^^
  File "/Users/evangoulden/Code/nornir_netauto/netauto.py", line 35, in backup_config
    result = task.run(task=napalm_get, getters=["config"])
             ^^^^^^^^^^^^^^^^^^^^^^^^^^^^^^^^^^^^^^^^^^^^^
  File "/Users/evangoulden/.local/share/virtualenvs/nornir_netauto-sh27gIds/lib/python3.11/site-packages/nornir/core/task.py", line 173, in run
    raise NornirSubTaskError(task=run_task, result=r)
nornir.core.exceptions.NornirSubTaskError: Subtask: napalm_get (failed)


2025-03-18 10:34:14,985 -  nornir.core -     INFO -        run() - Running task 'backup_config' with args {} on 3 hosts
2025-03-18 10:34:15,054 - nornir.core.task -    ERROR -      start() - Host 'fg-core-3850': task 'napalm_get' failed with traceback:
Traceback (most recent call last):
  File "/Users/evangoulden/.local/share/virtualenvs/nornir_netauto-sh27gIds/lib/python3.11/site-packages/netmiko/base_connection.py", line 1142, in establish_connection
    self.remote_conn_pre.connect(**ssh_connect_params)
  File "/Users/evangoulden/.local/share/virtualenvs/nornir_netauto-sh27gIds/lib/python3.11/site-packages/paramiko/client.py", line 409, in connect
    raise NoValidConnectionsError(errors)
paramiko.ssh_exception.NoValidConnectionsError: [Errno None] Unable to connect to port 22 on 10.141.14.1

During handling of the above exception, another exception occurred:

Traceback (most recent call last):
  File "/Users/evangoulden/.local/share/virtualenvs/nornir_netauto-sh27gIds/lib/python3.11/site-packages/napalm/base/base.py", line 114, in _netmiko_open
    self._netmiko_device = ConnectHandler(
                           ^^^^^^^^^^^^^^^
  File "/Users/evangoulden/.local/share/virtualenvs/nornir_netauto-sh27gIds/lib/python3.11/site-packages/netmiko/ssh_dispatcher.py", line 410, in ConnectHandler
    return ConnectionClass(*args, **kwargs)
           ^^^^^^^^^^^^^^^^^^^^^^^^^^^^^^^^
  File "/Users/evangoulden/.local/share/virtualenvs/nornir_netauto-sh27gIds/lib/python3.11/site-packages/netmiko/base_connection.py", line 493, in __init__
    self._open()
  File "/Users/evangoulden/.local/share/virtualenvs/nornir_netauto-sh27gIds/lib/python3.11/site-packages/netmiko/base_connection.py", line 498, in _open
    self.establish_connection()
  File "/Users/evangoulden/.local/share/virtualenvs/nornir_netauto-sh27gIds/lib/python3.11/site-packages/netmiko/base_connection.py", line 1164, in establish_connection
    raise NetmikoTimeoutException(msg)
netmiko.exceptions.NetmikoTimeoutException: TCP connection to device failed.

Common causes of this problem are:
1. Incorrect hostname or IP address.
2. Wrong TCP port.
3. Intermediate firewall blocking access.

Device settings: cisco_ios 10.141.14.1:22



During handling of the above exception, another exception occurred:

Traceback (most recent call last):
  File "/Users/evangoulden/.local/share/virtualenvs/nornir_netauto-sh27gIds/lib/python3.11/site-packages/nornir/core/task.py", line 98, in start
    r = self.task(self, **self.params)
        ^^^^^^^^^^^^^^^^^^^^^^^^^^^^^^
  File "/Users/evangoulden/.local/share/virtualenvs/nornir_netauto-sh27gIds/lib/python3.11/site-packages/nornir_napalm/plugins/tasks/napalm_get.py", line 32, in napalm_get
    device = task.host.get_connection(CONNECTION_NAME, task.nornir.config)
             ^^^^^^^^^^^^^^^^^^^^^^^^^^^^^^^^^^^^^^^^^^^^^^^^^^^^^^^^^^^^^
  File "/Users/evangoulden/.local/share/virtualenvs/nornir_netauto-sh27gIds/lib/python3.11/site-packages/nornir/core/inventory.py", line 476, in get_connection
    self.open_connection(
  File "/Users/evangoulden/.local/share/virtualenvs/nornir_netauto-sh27gIds/lib/python3.11/site-packages/nornir/core/inventory.py", line 528, in open_connection
    conn_obj.open(
  File "/Users/evangoulden/.local/share/virtualenvs/nornir_netauto-sh27gIds/lib/python3.11/site-packages/nornir_napalm/plugins/connections/__init__.py", line 57, in open
    connection.open()
  File "/Users/evangoulden/.local/share/virtualenvs/nornir_netauto-sh27gIds/lib/python3.11/site-packages/napalm/ios/ios.py", line 173, in open
    self.device = self._netmiko_open(
                  ^^^^^^^^^^^^^^^^^^^
  File "/Users/evangoulden/.local/share/virtualenvs/nornir_netauto-sh27gIds/lib/python3.11/site-packages/napalm/base/base.py", line 123, in _netmiko_open
    raise ConnectionException("Cannot connect to {}".format(self.hostname))
napalm.base.exceptions.ConnectionException: Cannot connect to 10.141.14.1

2025-03-18 10:34:15,054 - nornir.core.task -    ERROR -      start() - Host 'fg-core-3850': task 'backup_config' failed with traceback:
Traceback (most recent call last):
  File "/Users/evangoulden/.local/share/virtualenvs/nornir_netauto-sh27gIds/lib/python3.11/site-packages/nornir/core/task.py", line 98, in start
    r = self.task(self, **self.params)
        ^^^^^^^^^^^^^^^^^^^^^^^^^^^^^^
  File "/Users/evangoulden/Code/nornir_netauto/netauto.py", line 35, in backup_config
    result = task.run(task=napalm_get, getters=["config"])
             ^^^^^^^^^^^^^^^^^^^^^^^^^^^^^^^^^^^^^^^^^^^^^
  File "/Users/evangoulden/.local/share/virtualenvs/nornir_netauto-sh27gIds/lib/python3.11/site-packages/nornir/core/task.py", line 173, in run
    raise NornirSubTaskError(task=run_task, result=r)
nornir.core.exceptions.NornirSubTaskError: Subtask: napalm_get (failed)


2025-03-18 10:40:04,931 -  nornir.core -     INFO -        run() - Running task 'backup_config' with args {} on 3 hosts
2025-03-18 10:40:04,975 - nornir.core.task -    ERROR -      start() - Host 'fg-core-3850': task 'napalm_get' failed with traceback:
Traceback (most recent call last):
  File "/Users/evangoulden/.local/share/virtualenvs/nornir_netauto-sh27gIds/lib/python3.11/site-packages/netmiko/base_connection.py", line 1142, in establish_connection
    self.remote_conn_pre.connect(**ssh_connect_params)
  File "/Users/evangoulden/.local/share/virtualenvs/nornir_netauto-sh27gIds/lib/python3.11/site-packages/paramiko/client.py", line 409, in connect
    raise NoValidConnectionsError(errors)
paramiko.ssh_exception.NoValidConnectionsError: [Errno None] Unable to connect to port 22 on 10.141.14.1

During handling of the above exception, another exception occurred:

Traceback (most recent call last):
  File "/Users/evangoulden/.local/share/virtualenvs/nornir_netauto-sh27gIds/lib/python3.11/site-packages/napalm/base/base.py", line 114, in _netmiko_open
    self._netmiko_device = ConnectHandler(
                           ^^^^^^^^^^^^^^^
  File "/Users/evangoulden/.local/share/virtualenvs/nornir_netauto-sh27gIds/lib/python3.11/site-packages/netmiko/ssh_dispatcher.py", line 410, in ConnectHandler
    return ConnectionClass(*args, **kwargs)
           ^^^^^^^^^^^^^^^^^^^^^^^^^^^^^^^^
  File "/Users/evangoulden/.local/share/virtualenvs/nornir_netauto-sh27gIds/lib/python3.11/site-packages/netmiko/base_connection.py", line 493, in __init__
    self._open()
  File "/Users/evangoulden/.local/share/virtualenvs/nornir_netauto-sh27gIds/lib/python3.11/site-packages/netmiko/base_connection.py", line 498, in _open
    self.establish_connection()
  File "/Users/evangoulden/.local/share/virtualenvs/nornir_netauto-sh27gIds/lib/python3.11/site-packages/netmiko/base_connection.py", line 1164, in establish_connection
    raise NetmikoTimeoutException(msg)
netmiko.exceptions.NetmikoTimeoutException: TCP connection to device failed.

Common causes of this problem are:
1. Incorrect hostname or IP address.
2. Wrong TCP port.
3. Intermediate firewall blocking access.

Device settings: cisco_ios 10.141.14.1:22



During handling of the above exception, another exception occurred:

Traceback (most recent call last):
  File "/Users/evangoulden/.local/share/virtualenvs/nornir_netauto-sh27gIds/lib/python3.11/site-packages/nornir/core/task.py", line 98, in start
    r = self.task(self, **self.params)
        ^^^^^^^^^^^^^^^^^^^^^^^^^^^^^^
  File "/Users/evangoulden/.local/share/virtualenvs/nornir_netauto-sh27gIds/lib/python3.11/site-packages/nornir_napalm/plugins/tasks/napalm_get.py", line 32, in napalm_get
    device = task.host.get_connection(CONNECTION_NAME, task.nornir.config)
             ^^^^^^^^^^^^^^^^^^^^^^^^^^^^^^^^^^^^^^^^^^^^^^^^^^^^^^^^^^^^^
  File "/Users/evangoulden/.local/share/virtualenvs/nornir_netauto-sh27gIds/lib/python3.11/site-packages/nornir/core/inventory.py", line 476, in get_connection
    self.open_connection(
  File "/Users/evangoulden/.local/share/virtualenvs/nornir_netauto-sh27gIds/lib/python3.11/site-packages/nornir/core/inventory.py", line 528, in open_connection
    conn_obj.open(
  File "/Users/evangoulden/.local/share/virtualenvs/nornir_netauto-sh27gIds/lib/python3.11/site-packages/nornir_napalm/plugins/connections/__init__.py", line 57, in open
    connection.open()
  File "/Users/evangoulden/.local/share/virtualenvs/nornir_netauto-sh27gIds/lib/python3.11/site-packages/napalm/ios/ios.py", line 173, in open
    self.device = self._netmiko_open(
                  ^^^^^^^^^^^^^^^^^^^
  File "/Users/evangoulden/.local/share/virtualenvs/nornir_netauto-sh27gIds/lib/python3.11/site-packages/napalm/base/base.py", line 123, in _netmiko_open
    raise ConnectionException("Cannot connect to {}".format(self.hostname))
napalm.base.exceptions.ConnectionException: Cannot connect to 10.141.14.1

2025-03-18 10:40:04,975 - nornir.core.task -    ERROR -      start() - Host 'fg-core-3850': task 'backup_config' failed with traceback:
Traceback (most recent call last):
  File "/Users/evangoulden/.local/share/virtualenvs/nornir_netauto-sh27gIds/lib/python3.11/site-packages/nornir/core/task.py", line 98, in start
    r = self.task(self, **self.params)
        ^^^^^^^^^^^^^^^^^^^^^^^^^^^^^^
  File "/Users/evangoulden/Code/nornir_netauto/netauto.py", line 36, in backup_config
    result = task.run(task=napalm_get, getters=["config"])
             ^^^^^^^^^^^^^^^^^^^^^^^^^^^^^^^^^^^^^^^^^^^^^
  File "/Users/evangoulden/.local/share/virtualenvs/nornir_netauto-sh27gIds/lib/python3.11/site-packages/nornir/core/task.py", line 173, in run
    raise NornirSubTaskError(task=run_task, result=r)
nornir.core.exceptions.NornirSubTaskError: Subtask: napalm_get (failed)


